Workbook

Sheet Workshop
A1: Demand forecasting workshop
A2: South Africa • 7 October 2026 • Proposed direction and provisional current-model examples
A4: Discussion | B4: Starting position | C4: Decision to record | D4: Lead / reviewer | E4: Agreed decision | F4: Next action / date
A5: Purpose | B5: Start with Baseline; follow formulas to sector blocks, Model run and Evidence. | C5: Source selection holds each historical comparator choice. FIASA is provisional; HML remains last. | D5: Nigel + Manish
A6: 1. Segment methods | B6: Methods sheet distinguishes the existing engine from the proposed method. | C6: Agree method, segment boundaries and missing components. | D6: Manish / Nigel
A7: 2. Geography | B7: Use national allocation where local evidence is weak; provincial calculations where defensible. | C7: Choose method by segment and define sales versus consumption location. | D7: Manish / Nigel
A8: 3. Worked examples | B8: Excel recalculates source choices, linked reporting totals, unit conversions and differences. | C8: Engine results are a frozen Python run. Input/scenario changes require a Python rerun and refreshed export. | D8: Manish / Nigel
A9: 4. Input ranges | B9: HML contains existing proposed demand ranges plus blank brackets for missing drivers. | C9: Agree low / medium / high inputs, reference case and annual paths. | D9: Nigel / Henry
A10: 5. Scenario combinations | B10: A higher input can raise or lower demand. Medium is not an approved baseline. | C10: Select compatible inputs; assess demand and supply independently. | D10: Nigel / Henry
A11: 6. Acceptance | B11: Review corrections before engine integration. | C11: Record evidence, decision, owner and next review trigger. | D11: Nigel
A12: Example scope | B12: Current high_demand scenario, vintage 2026. This is one existing case, not the proposed medium case. | C12: 2022–2023 model backcast; 2024–2035 model horizon. No row is observed merely because its year is historical. | D12: All readers
A13: Editable cells | B13: Yellow = missing/discussion inputs; blue = staged observations; green = current model or reporting calculations. | C13: Full-year observations stay in year columns. D may contain a clearly dated latest YTD/snapshot or older anchor. | D13: All readers
A14: Calculation boundary | B14: Demand figures are snapshots from the Python engine. Editing a discussion input does not rerun the engine. | C14: Only explicit reconciliation / allocation formulas recalculate in Excel. | D14: Manish
A15: Provincial example | B15: 2022 observed provincial petrol/diesel and Q1 2023 partial values are now shown below the allocation template. | C15: Sales location differs from consumption. No passenger allocation shares have been silently populated. | D15: Manish / Nigel
A16: Sources and run | B16: Recorded engine run: 2026-10-07T10:48:46.852505+00:00; commit 8c69f8333192483f19cd80911cb90fcd0943eb6b; high_demand; vintage 2026. | C16: Input and evidence SHA256 hashes are retained in workshop_data.json; no new model assumptions adopted. | D16: 2026 draft vintage
A17: Acceptance boundary | B17: 54 open exceptions at workbook preparation. Current inputs and outputs remain provisional. | C17: No source approval, peer-review completion or client acceptance is inferred. | D17: Nigel

Sheet Baseline
A1: Demand baseline and reconciliation
A2: Linked demand comparison. Full definitions: Notes. Historical sources: Source selection.
A4: Driver / output | B4: Unit | C4: Role | D4: Scalar / latest value | E4: Definition / period | F4: 2022 | G4: 2023 | H4: 2024 | I4: 2025 | J4: 2026 | K4: 2027 | L4: 2028 | M4: 2029 | N4: 2030 | O4: 2031 | P4: 2032 | Q4: 2033 | R4: 2034 | S4: 2035 | T4: Coverage / status | U4: Source | V4: Missing evidence / next action
A5: Petrol: national product comparison
A6: Selected historical petrol sales | B6: million L/year | C6: Linked observation | E6: Selected historical sales; see Source selection. [N001] | F6: =IF(ISNUMBER('Source selection'!F5),'Source selection'!F5,"") | G6: =IF(ISNUMBER('Source selection'!F6),'Source selection'!F6,"") | H6: =IF(ISNUMBER('Source selection'!F7),'Source selection'!F7,"") | I6: =IF(ISNUMBER('Source selection'!F8),'Source selection'!F8,"") | J6: =IF(ISNUMBER('Source selection'!F9),'Source selection'!F9,"") | T6: Working comparator; not approved | U6: Source selection → Evidence | V6: Manish reconciles scope/revisions; Nigel accepts source.
A7: Historical source / status | B7: text | C7: Selection status | E7: Selected source, or unresolved when unavailable. [N002] | F7: =IF(ISNUMBER('Source selection'!F5),'Source selection'!E5,"Unresolved") | G7: =IF(ISNUMBER('Source selection'!F6),'Source selection'!E6,"Unresolved") | H7: =IF(ISNUMBER('Source selection'!F7),'Source selection'!E7,"Unresolved") | I7: =IF(ISNUMBER('Source selection'!F8),'Source selection'!E8,"Unresolved") | J7: =IF(ISNUMBER('Source selection'!F9),'Source selection'!E9,"Unresolved") | T7: Not an additional demand series | U7: Source selection | V7: Review selected source before calibration.
A8: Current model road petrol | B8: million L/year | C8: Model output | E8: Passenger + LCV petrol. All-grade sales comparison. [N003] | F8: =IF(ISNUMBER('Petrol'!F23),'Petrol'!F23/1000000,"") | G8: =IF(ISNUMBER('Petrol'!G23),'Petrol'!G23/1000000,"") | H8: =IF(ISNUMBER('Petrol'!H23),'Petrol'!H23/1000000,"") | I8: =IF(ISNUMBER('Petrol'!I23),'Petrol'!I23/1000000,"") | J8: =IF(ISNUMBER('Petrol'!J23),'Petrol'!J23/1000000,"") | K8: =IF(ISNUMBER('Petrol'!K23),'Petrol'!K23/1000000,"") | L8: =IF(ISNUMBER('Petrol'!L23),'Petrol'!L23/1000000,"") | M8: =IF(ISNUMBER('Petrol'!M23),'Petrol'!M23/1000000,"") | ... S8: =IF(ISNUMBER('Petrol'!S23),'Petrol'!S23/1000000,"") | T8: 2026 vintage; current high_demand case; provisional. | U8: Petrol row 23 → Model run → Python engine | V8: Validate inputs and reconcile against observed data.
A9: Model less selected historical sales | B9: million L/year | C9: Reporting formula | E9: Model minus selected sales; scope requires reconciliation. [N004] | F9: =IF(COUNT(F6,F8)<2,"",F8-F6) | G9: =IF(COUNT(G6,G8)<2,"",G8-G6) | H9: =IF(COUNT(H6,H8)<2,"",H8-H6) | I9: =IF(COUNT(I6,I8)<2,"",I8-I6) | J9: =IF(COUNT(J6,J8)<2,"",J8-J6) | K9: =IF(COUNT(K6,K8)<2,"",K8-K6) | L9: =IF(COUNT(L6,L8)<2,"",L8-L6) | M9: =IF(COUNT(M6,M8)<2,"",M8-M6) | ... S9: =IF(COUNT(S6,S8)<2,"",S8-S6) | T9: Only where both values exist. | V9: G01: reconcile grade/segment scope.
A11: Diesel: segments and national product comparison
A12: Selected historical diesel sales | B12: million L/year | C12: Linked observation | E12: Selected historical sales; see Source selection. [N005] | F12: =IF(ISNUMBER('Source selection'!F10),'Source selection'!F10,"") | G12: =IF(ISNUMBER('Source selection'!F11),'Source selection'!F11,"") | H12: =IF(ISNUMBER('Source selection'!F12),'Source selection'!F12,"") | I12: =IF(ISNUMBER('Source selection'!F13),'Source selection'!F13,"") | J12: =IF(ISNUMBER('Source selection'!F14),'Source selection'!F14,"") | T12: Working comparator; not approved | U12: Source selection → Evidence | V12: Manish reconciles scope/revisions; Nigel accepts source.
A13: Historical source / status | B13: text | C13: Selection status | E13: Selected source, or unresolved when unavailable. [N006] | F13: =IF(ISNUMBER('Source selection'!F10),'Source selection'!E10,"Unresolved") | G13: =IF(ISNUMBER('Source selection'!F11),'Source selection'!E11,"Unresolved") | H13: =IF(ISNUMBER('Source selection'!F12),'Source selection'!E12,"Unresolved") | I13: =IF(ISNUMBER('Source selection'!F13),'Source selection'!E13,"Unresolved") | J13: =IF(ISNUMBER('Source selection'!F14),'Source selection'!E14,"Unresolved") | T13: Not an additional demand series | U13: Source selection | V13: Review selected source before calibration.
A14: All road diesel | B14: million L/year | C14: Model output | E14: Passenger + LCV + HCV diesel. [N007] | F14: =IF(ISNUMBER('Freight'!F57),'Freight'!F57/1,"") | G14: =IF(ISNUMBER('Freight'!G57),'Freight'!G57/1,"") | H14: =IF(ISNUMBER('Freight'!H57),'Freight'!H57/1,"") | I14: =IF(ISNUMBER('Freight'!I57),'Freight'!I57/1,"") | J14: =IF(ISNUMBER('Freight'!J57),'Freight'!J57/1,"") | K14: =IF(ISNUMBER('Freight'!K57),'Freight'!K57/1,"") | L14: =IF(ISNUMBER('Freight'!L57),'Freight'!L57/1,"") | M14: =IF(ISNUMBER('Freight'!M57),'Freight'!M57/1,"") | ... S14: =IF(ISNUMBER('Freight'!S57),'Freight'!S57/1,"") | T14: 2026 vintage; current high_demand case; provisional. | U14: Freight row 57 → Model run → Python engine | V14: Validate inputs and reconcile against observed data.
A15: Grid OCGT diesel | B15: million L/year | C15: Model output | E15: Grid OCGT model. Private backup not calibrated. [N008] | F15: =IF(ISNUMBER('Other demand'!F12),'Other demand'!F12/1,"") | G15: =IF(ISNUMBER('Other demand'!G12),'Other demand'!G12/1,"") | H15: =IF(ISNUMBER('Other demand'!H12),'Other demand'!H12/1,"") | I15: =IF(ISNUMBER('Other demand'!I12),'Other demand'!I12/1,"") | J15: =IF(ISNUMBER('Other demand'!J12),'Other demand'!J12/1,"") | K15: =IF(ISNUMBER('Other demand'!K12),'Other demand'!K12/1,"") | L15: =IF(ISNUMBER('Other demand'!L12),'Other demand'!L12/1,"") | M15: =IF(ISNUMBER('Other demand'!M12),'Other demand'!M12/1,"") | ... S15: =IF(ISNUMBER('Other demand'!S12),'Other demand'!S12/1,"") | T15: 2026 vintage; current high_demand case; provisional. | U15: Other demand row 12 → Model run → Python engine | V15: Validate inputs and reconcile against observed data.
A16: Agricultural diesel | B16: million L/year | C16: Model output | E16: GDP/capita method; provisional 2024 fuel baseline. [N009] | F16: =IF(ISNUMBER('Agriculture'!F13),'Agriculture'!F13/1,"") | G16: =IF(ISNUMBER('Agriculture'!G13),'Agriculture'!G13/1,"") | H16: =IF(ISNUMBER('Agriculture'!H13),'Agriculture'!H13/1,"") | I16: =IF(ISNUMBER('Agriculture'!I13),'Agriculture'!I13/1,"") | J16: =IF(ISNUMBER('Agriculture'!J13),'Agriculture'!J13/1,"") | K16: =IF(ISNUMBER('Agriculture'!K13),'Agriculture'!K13/1,"") | L16: =IF(ISNUMBER('Agriculture'!L13),'Agriculture'!L13/1,"") | M16: =IF(ISNUMBER('Agriculture'!M13),'Agriculture'!M13/1,"") | ... S16: =IF(ISNUMBER('Agriculture'!S13),'Agriculture'!S13/1,"") | T16: 2026 vintage; current high_demand case; provisional. | U16: Agriculture row 13 → Model run → Python engine | V16: Validate inputs and reconcile against observed data.
A17: Combined industrial diesel | B17: million L/year | C17: Model output | E17: Manufacturing + mining + construction combined. [N010] | F17: =IF(ISNUMBER('Manufacturing'!F24),'Manufacturing'!F24/1,"") | G17: =IF(ISNUMBER('Manufacturing'!G24),'Manufacturing'!G24/1,"") | H17: =IF(ISNUMBER('Manufacturing'!H24),'Manufacturing'!H24/1,"") | I17: =IF(ISNUMBER('Manufacturing'!I24),'Manufacturing'!I24/1,"") | J17: =IF(ISNUMBER('Manufacturing'!J24),'Manufacturing'!J24/1,"") | K17: =IF(ISNUMBER('Manufacturing'!K24),'Manufacturing'!K24/1,"") | L17: =IF(ISNUMBER('Manufacturing'!L24),'Manufacturing'!L24/1,"") | M17: =IF(ISNUMBER('Manufacturing'!M24),'Manufacturing'!M24/1,"") | ... S17: =IF(ISNUMBER('Manufacturing'!S24),'Manufacturing'!S24/1,"") | T17: 2026 vintage; current high_demand case; provisional. | U17: Manufacturing row 24 → Model run → Python engine | V17: Validate inputs and reconcile against observed data.
A18: Marine diesel | B18: million L/year | C18: Model output | E18: Marine diesel; 2022–23 model history unavailable. [N011] | F18: =IF(ISNUMBER('Other demand'!F34),'Other demand'!F34/1,"") | G18: =IF(ISNUMBER('Other demand'!G34),'Other demand'!G34/1,"") | H18: =IF(ISNUMBER('Other demand'!H34),'Other demand'!H34/1,"") | I18: =IF(ISNUMBER('Other demand'!I34),'Other demand'!I34/1,"") | J18: =IF(ISNUMBER('Other demand'!J34),'Other demand'!J34/1,"") | K18: =IF(ISNUMBER('Other demand'!K34),'Other demand'!K34/1,"") | L18: =IF(ISNUMBER('Other demand'!L34),'Other demand'!L34/1,"") | M18: =IF(ISNUMBER('Other demand'!M34),'Other demand'!M34/1,"") | ... S18: =IF(ISNUMBER('Other demand'!S34),'Other demand'!S34/1,"") | T18: 2026 vintage; current high_demand case; provisional. | U18: Other demand row 34 → Model run → Python engine | V18: Validate inputs and reconcile against observed data.
A19: Total model diesel | B19: million L/year | C19: Reporting formula | E19: Sum road, OCGT, agriculture, industry and marine. [N012] | F19: =IF(COUNT(F14:F18)<5,"",SUM(F14:F18)) | G19: =IF(COUNT(G14:G18)<5,"",SUM(G14:G18)) | H19: =IF(COUNT(H14:H18)<5,"",SUM(H14:H18)) | I19: =IF(COUNT(I14:I18)<5,"",SUM(I14:I18)) | J19: =IF(COUNT(J14:J18)<5,"",SUM(J14:J18)) | K19: =IF(COUNT(K14:K18)<5,"",SUM(K14:K18)) | L19: =IF(COUNT(L14:L18)<5,"",SUM(L14:L18)) | M19: =IF(COUNT(M14:M18)<5,"",SUM(M14:M18)) | ... S19: =IF(COUNT(S14:S18)<5,"",SUM(S14:S18)) | T19: Blank if any component is missing. | V19: G01/G12: reconcile domestic sales and bunkers.
A20: Model less selected historical sales | B20: million L/year | C20: Reporting formula | E20: Model minus selected sales; scope requires reconciliation. [N013] | F20: =IF(COUNT(F12,F19)<2,"",F19-F12) | G20: =IF(COUNT(G12,G19)<2,"",G19-G12) | H20: =IF(COUNT(H12,H19)<2,"",H19-H12) | I20: =IF(COUNT(I12,I19)<2,"",I19-I12) | J20: =IF(COUNT(J12,J19)<2,"",J19-J12) | K20: =IF(COUNT(K12,K19)<2,"",K19-K12) | L20: =IF(COUNT(L12,L19)<2,"",L19-L12) | M20: =IF(COUNT(M12,M19)<2,"",M19-M12) | ... S20: =IF(COUNT(S12,S19)<2,"",S19-S12) | T20: Only matched available years. | V20: G01: reconcile units, coverage and sales basis.
A21: Manufacturing-only baseline | B21: million L/year | C21: Missing input | E21: Included within industrial total; separate baseline missing. [N014] | T21: No matched observed 2022+ fuel series located. | U21: https://github.com/Africa-International-Advisors/liq… [N015] | V21: G06: reconcile manufacturing subsectors and scope.
A22: Mining-only baseline | B22: million L/year | C22: Missing input | D22: =IF(ISNUMBER('Mining'!D31),'Mining'!D31,"") | E22: 2021 anchor only; included within industrial total. [N016] | T22: 2021 anchor available; 2022+ fuel series missing. | U22: https://github.com/Africa-International-Advisors/liq… [N017] | V22: G07: verify site/end-use coverage and newer fuel data.
A23: Private backup / other diesel | B23: million L/year | C23: Missing input | E23: Baseline and sector overlap unresolved. [N018] | T23: Separate coverage and baseline unresolved. | V23: G09: source fuel/generation evidence; count once.
A25: Jet: national product comparison
A26: Selected historical jet sales | B26: million L/year | C26: Linked observation | E26: Selected historical sales; see Source selection. [N019] | F26: =IF(ISNUMBER('Source selection'!F15),'Source selection'!F15,"") | G26: =IF(ISNUMBER('Source selection'!F16),'Source selection'!F16,"") | H26: =IF(ISNUMBER('Source selection'!F17),'Source selection'!F17,"") | I26: =IF(ISNUMBER('Source selection'!F18),'Source selection'!F18,"") | J26: =IF(ISNUMBER('Source selection'!F19),'Source selection'!F19,"") | T26: Working comparator; not approved | U26: Source selection → Evidence | V26: Manish reconciles scope/revisions; Nigel accepts source.
A27: Historical source / status | B27: text | C27: Selection status | E27: Selected source, or unresolved when unavailable. [N020] | F27: =IF(ISNUMBER('Source selection'!F15),'Source selection'!E15,"Unresolved") | G27: =IF(ISNUMBER('Source selection'!F16),'Source selection'!E16,"Unresolved") | H27: =IF(ISNUMBER('Source selection'!F17),'Source selection'!E17,"Unresolved") | I27: =IF(ISNUMBER('Source selection'!F18),'Source selection'!E18,"Unresolved") | J27: =IF(ISNUMBER('Source selection'!F19),'Source selection'!E19,"Unresolved") | T27: Not an additional demand series | U27: Source selection | V27: Review selected source before calibration.
A28: Current model jet | B28: million L/year | C28: Model output | E28: GDP/capita and passenger regression. [N021] | F28: =IF(ISNUMBER('Other demand'!F20),'Other demand'!F20/1,"") | G28: =IF(ISNUMBER('Other demand'!G20),'Other demand'!G20/1,"") | H28: =IF(ISNUMBER('Other demand'!H20),'Other demand'!H20/1,"") | I28: =IF(ISNUMBER('Other demand'!I20),'Other demand'!I20/1,"") | J28: =IF(ISNUMBER('Other demand'!J20),'Other demand'!J20/1,"") | K28: =IF(ISNUMBER('Other demand'!K20),'Other demand'!K20/1,"") | L28: =IF(ISNUMBER('Other demand'!L20),'Other demand'!L20/1,"") | M28: =IF(ISNUMBER('Other demand'!M20),'Other demand'!M20/1,"") | ... S28: =IF(ISNUMBER('Other demand'!S20),'Other demand'!S20/1,"") | T28: 2026 vintage; current high_demand case; provisional. | U28: Other demand row 20 → Model run → Python engine | V28: Validate inputs and reconcile against observed data.
A29: Model less selected historical sales | B29: million L/year | C29: Reporting formula | E29: Model minus selected sales; reconcile coverage. [N022] | F29: =IF(COUNT(F26,F28)<2,"",F28-F26) | G29: =IF(COUNT(G26,G28)<2,"",G28-G26) | H29: =IF(COUNT(H26,H28)<2,"",H28-H26) | I29: =IF(COUNT(I26,I28)<2,"",I28-I26) | J29: =IF(COUNT(J26,J28)<2,"",J28-J26) | K29: =IF(COUNT(K26,K28)<2,"",K28-K26) | L29: =IF(COUNT(L26,L28)<2,"",L28-L26) | M29: =IF(COUNT(M26,M28)<2,"",M28-M26) | ... S29: =IF(COUNT(S26,S28)<2,"",S28-S26) | T29: Only where both values exist. | V29: G10: calibrate aircraft/airport coverage.
A31: Marine fuel oil: scope is narrower than total national fuel oil
A32: Selected historical fuel oil sales | B32: million L/year | C32: Linked observation | E32: National fuel-oil sales; includes more than marine. [N023] | F32: =IF(ISNUMBER('Source selection'!F20),'Source selection'!F20,"") | G32: =IF(ISNUMBER('Source selection'!F21),'Source selection'!F21,"") | H32: =IF(ISNUMBER('Source selection'!F22),'Source selection'!F22,"") | I32: =IF(ISNUMBER('Source selection'!F23),'Source selection'!F23,"") | J32: =IF(ISNUMBER('Source selection'!F24),'Source selection'!F24,"") | T32: Working comparator; not approved | U32: Source selection → Evidence | V32: Manish reconciles scope/revisions; Nigel accepts source.
A33: Current model marine fuel oil | B33: million L/year | C33: Model output | E33: Marine fuel oil only; narrower than national sales. [N024] | F33: =IF(ISNUMBER('Other demand'!F35),'Other demand'!F35/1,"") | G33: =IF(ISNUMBER('Other demand'!G35),'Other demand'!G35/1,"") | H33: =IF(ISNUMBER('Other demand'!H35),'Other demand'!H35/1,"") | I33: =IF(ISNUMBER('Other demand'!I35),'Other demand'!I35/1,"") | J33: =IF(ISNUMBER('Other demand'!J35),'Other demand'!J35/1,"") | K33: =IF(ISNUMBER('Other demand'!K35),'Other demand'!K35/1,"") | L33: =IF(ISNUMBER('Other demand'!L35),'Other demand'!L35/1,"") | M33: =IF(ISNUMBER('Other demand'!M35),'Other demand'!M35/1,"") | ... S33: =IF(ISNUMBER('Other demand'!S35),'Other demand'!S35/1,"") | T33: 2026 vintage; current high_demand case; provisional. | U33: Other demand row 35 → Model run → Python engine | V33: Validate inputs and reconcile against observed data.
A35: Baseline selection | B35: decision | C35: Missing input | E35: Historical comparator selection is explicit on Source selection.… [N025] | T35: Review before calibration. | V35: Nigel selects baseline after Manish reconciliation.
A36: Latest partial periods | B36: reading note | C36: Evidence note | E36: Full annual observations occupy year columns. A separate D value… [N026] | T36: FY OCGT explicitly uses year ending March. | V36: Do not annualise partial 2026 observations silently.
A37: Run provenance | B37: record | C37: Evidence note | E37: Commit 8c69f8333192483f19cd80911cb90fcd0943eb6b; vintage 2026;… [N027] | T37: 54 open governance exceptions at preparation. | U37: https://github.com/Africa-International-Advisors/liq… [N028] | V37: Outputs remain provisional.

Sheet Source selection
A1: Source selection
A2: Working comparator choice per fuel/year • FIASA retains the previous comparison; no business approval inferred.
A4: Product | B4: Year | C4: FIASA candidate | D4: Department candidate | E4: Working selection | F4: Selected million L | G4: Availability / review | H4: Owner | I4: Decision basis | J4: Review trigger
A5: petrol | B5: 2022 | C5: =IF(ISNUMBER('Evidence'!F5),'Evidence'!F5,"") | D5: =IF(ISNUMBER('Evidence'!F6),'Evidence'!F6,"") | E5: Department | F5: =IF(E5="FIASA",IF(ISNUMBER(C5),C5,""),IF(E5="Department",IF(ISNUMBER(D5),D5,""),"")) | G5: =IF(E5="Unresolved","No source selected",IF(ISNUMBER(F5),"Working choice - awaiting review","Selected source missing")) | H5: Nigel / Manish | I5: Working comparator only; retain prior FIASA comparison pending reconciliation. | J5: Before baseline acceptance
A6: petrol | B6: 2023 | C6: =IF(ISNUMBER('Evidence'!G5),'Evidence'!G5,"") | D6: =IF(ISNUMBER('Evidence'!G6),'Evidence'!G6,"") | E6: Department | F6: =IF(E6="FIASA",IF(ISNUMBER(C6),C6,""),IF(E6="Department",IF(ISNUMBER(D6),D6,""),"")) | G6: =IF(E6="Unresolved","No source selected",IF(ISNUMBER(F6),"Working choice - awaiting review","Selected source missing")) | H6: Nigel / Manish | I6: Working comparator only; retain prior FIASA comparison pending reconciliation. | J6: Before baseline acceptance
A7: petrol | B7: 2024 | C7: =IF(ISNUMBER('Evidence'!H5),'Evidence'!H5,"") | D7: =IF(ISNUMBER('Evidence'!H6),'Evidence'!H6,"") | E7: FIASA | F7: =IF(E7="FIASA",IF(ISNUMBER(C7),C7,""),IF(E7="Department",IF(ISNUMBER(D7),D7,""),"")) | G7: =IF(E7="Unresolved","No source selected",IF(ISNUMBER(F7),"Working choice - awaiting review","Selected source missing")) | H7: Nigel / Manish | I7: Working comparator only; retain prior FIASA comparison pending reconciliation. | J7: Before baseline acceptance
A8: petrol | B8: 2025 | C8: =IF(ISNUMBER('Evidence'!I5),'Evidence'!I5,"") | D8: =IF(ISNUMBER('Evidence'!I6),'Evidence'!I6,"") | E8: Unresolved | F8: =IF(E8="FIASA",IF(ISNUMBER(C8),C8,""),IF(E8="Department",IF(ISNUMBER(D8),D8,""),"")) | G8: =IF(E8="Unresolved","No source selected",IF(ISNUMBER(F8),"Working choice - awaiting review","Selected source missing")) | H8: Nigel / Manish | I8: Working comparator only; retain prior FIASA comparison pending reconciliation. | J8: Before baseline acceptance
A9: petrol | B9: 2026 | C9: =IF(ISNUMBER('Evidence'!J5),'Evidence'!J5,"") | D9: =IF(ISNUMBER('Evidence'!J6),'Evidence'!J6,"") | E9: Unresolved | F9: =IF(E9="FIASA",IF(ISNUMBER(C9),C9,""),IF(E9="Department",IF(ISNUMBER(D9),D9,""),"")) | G9: =IF(E9="Unresolved","No source selected",IF(ISNUMBER(F9),"Working choice - awaiting review","Selected source missing")) | H9: Nigel / Manish | I9: Working comparator only; retain prior FIASA comparison pending reconciliation. | J9: Before baseline acceptance
A10: diesel | B10: 2022 | C10: =IF(ISNUMBER('Evidence'!F7),'Evidence'!F7,"") | D10: =IF(ISNUMBER('Evidence'!F8),'Evidence'!F8,"") | E10: Department | F10: =IF(E10="FIASA",IF(ISNUMBER(C10),C10,""),IF(E10="Department",IF(ISNUMBER(D10),D10,""),"")) | G10: =IF(E10="Unresolved","No source selected",IF(ISNUMBER(F10),"Working choice - awaiting review","Selected source missing")) | H10: Nigel / Manish | I10: Working comparator only; retain prior FIASA comparison pending reconciliation. | J10: Before baseline acceptance
A11: diesel | B11: 2023 | C11: =IF(ISNUMBER('Evidence'!G7),'Evidence'!G7,"") | D11: =IF(ISNUMBER('Evidence'!G8),'Evidence'!G8,"") | E11: Department | F11: =IF(E11="FIASA",IF(ISNUMBER(C11),C11,""),IF(E11="Department",IF(ISNUMBER(D11),D11,""),"")) | G11: =IF(E11="Unresolved","No source selected",IF(ISNUMBER(F11),"Working choice - awaiting review","Selected source missing")) | H11: Nigel / Manish | I11: Working comparator only; retain prior FIASA comparison pending reconciliation. | J11: Before baseline acceptance
A12: diesel | B12: 2024 | C12: =IF(ISNUMBER('Evidence'!H7),'Evidence'!H7,"") | D12: =IF(ISNUMBER('Evidence'!H8),'Evidence'!H8,"") | E12: FIASA | F12: =IF(E12="FIASA",IF(ISNUMBER(C12),C12,""),IF(E12="Department",IF(ISNUMBER(D12),D12,""),"")) | G12: =IF(E12="Unresolved","No source selected",IF(ISNUMBER(F12),"Working choice - awaiting review","Selected source missing")) | H12: Nigel / Manish | I12: Working comparator only; retain prior FIASA comparison pending reconciliation. | J12: Before baseline acceptance
A13: diesel | B13: 2025 | C13: =IF(ISNUMBER('Evidence'!I7),'Evidence'!I7,"") | D13: =IF(ISNUMBER('Evidence'!I8),'Evidence'!I8,"") | E13: Unresolved | F13: =IF(E13="FIASA",IF(ISNUMBER(C13),C13,""),IF(E13="Department",IF(ISNUMBER(D13),D13,""),"")) | G13: =IF(E13="Unresolved","No source selected",IF(ISNUMBER(F13),"Working choice - awaiting review","Selected source missing")) | H13: Nigel / Manish | I13: Working comparator only; retain prior FIASA comparison pending reconciliation. | J13: Before baseline acceptance
A14: diesel | B14: 2026 | C14: =IF(ISNUMBER('Evidence'!J7),'Evidence'!J7,"") | D14: =IF(ISNUMBER('Evidence'!J8),'Evidence'!J8,"") | E14: Unresolved | F14: =IF(E14="FIASA",IF(ISNUMBER(C14),C14,""),IF(E14="Department",IF(ISNUMBER(D14),D14,""),"")) | G14: =IF(E14="Unresolved","No source selected",IF(ISNUMBER(F14),"Working choice - awaiting review","Selected source missing")) | H14: Nigel / Manish | I14: Working comparator only; retain prior FIASA comparison pending reconciliation. | J14: Before baseline acceptance
A15: jet | B15: 2022 | C15: =IF(ISNUMBER('Evidence'!F9),'Evidence'!F9,"") | D15: =IF(ISNUMBER('Evidence'!F10),'Evidence'!F10,"") | E15: Department | F15: =IF(E15="FIASA",IF(ISNUMBER(C15),C15,""),IF(E15="Department",IF(ISNUMBER(D15),D15,""),"")) | G15: =IF(E15="Unresolved","No source selected",IF(ISNUMBER(F15),"Working choice - awaiting review","Selected source missing")) | H15: Nigel / Manish | I15: Working comparator only; retain prior FIASA comparison pending reconciliation. | J15: Before baseline acceptance
A16: jet | B16: 2023 | C16: =IF(ISNUMBER('Evidence'!G9),'Evidence'!G9,"") | D16: =IF(ISNUMBER('Evidence'!G10),'Evidence'!G10,"") | E16: Department | F16: =IF(E16="FIASA",IF(ISNUMBER(C16),C16,""),IF(E16="Department",IF(ISNUMBER(D16),D16,""),"")) | G16: =IF(E16="Unresolved","No source selected",IF(ISNUMBER(F16),"Working choice - awaiting review","Selected source missing")) | H16: Nigel / Manish | I16: Working comparator only; retain prior FIASA comparison pending reconciliation. | J16: Before baseline acceptance
A17: jet | B17: 2024 | C17: =IF(ISNUMBER('Evidence'!H9),'Evidence'!H9,"") | D17: =IF(ISNUMBER('Evidence'!H10),'Evidence'!H10,"") | E17: FIASA | F17: =IF(E17="FIASA",IF(ISNUMBER(C17),C17,""),IF(E17="Department",IF(ISNUMBER(D17),D17,""),"")) | G17: =IF(E17="Unresolved","No source selected",IF(ISNUMBER(F17),"Working choice - awaiting review","Selected source missing")) | H17: Nigel / Manish | I17: Working comparator only; retain prior FIASA comparison pending reconciliation. | J17: Before baseline acceptance
A18: jet | B18: 2025 | C18: =IF(ISNUMBER('Evidence'!I9),'Evidence'!I9,"") | D18: =IF(ISNUMBER('Evidence'!I10),'Evidence'!I10,"") | E18: Unresolved | F18: =IF(E18="FIASA",IF(ISNUMBER(C18),C18,""),IF(E18="Department",IF(ISNUMBER(D18),D18,""),"")) | G18: =IF(E18="Unresolved","No source selected",IF(ISNUMBER(F18),"Working choice - awaiting review","Selected source missing")) | H18: Nigel / Manish | I18: Working comparator only; retain prior FIASA comparison pending reconciliation. | J18: Before baseline acceptance
A19: jet | B19: 2026 | C19: =IF(ISNUMBER('Evidence'!J9),'Evidence'!J9,"") | D19: =IF(ISNUMBER('Evidence'!J10),'Evidence'!J10,"") | E19: Unresolved | F19: =IF(E19="FIASA",IF(ISNUMBER(C19),C19,""),IF(E19="Department",IF(ISNUMBER(D19),D19,""),"")) | G19: =IF(E19="Unresolved","No source selected",IF(ISNUMBER(F19),"Working choice - awaiting review","Selected source missing")) | H19: Nigel / Manish | I19: Working comparator only; retain prior FIASA comparison pending reconciliation. | J19: Before baseline acceptance
A20: fuel_oil | B20: 2022 | C20: =IF(ISNUMBER('Evidence'!F11),'Evidence'!F11,"") | D20: =IF(ISNUMBER('Evidence'!F12),'Evidence'!F12,"") | E20: Department | F20: =IF(E20="FIASA",IF(ISNUMBER(C20),C20,""),IF(E20="Department",IF(ISNUMBER(D20),D20,""),"")) | G20: =IF(E20="Unresolved","No source selected",IF(ISNUMBER(F20),"Working choice - awaiting review","Selected source missing")) | H20: Nigel / Manish | I20: Working comparator only; retain prior FIASA comparison pending reconciliation. | J20: Before baseline acceptance
A21: fuel_oil | B21: 2023 | C21: =IF(ISNUMBER('Evidence'!G11),'Evidence'!G11,"") | D21: =IF(ISNUMBER('Evidence'!G12),'Evidence'!G12,"") | E21: Department | F21: =IF(E21="FIASA",IF(ISNUMBER(C21),C21,""),IF(E21="Department",IF(ISNUMBER(D21),D21,""),"")) | G21: =IF(E21="Unresolved","No source selected",IF(ISNUMBER(F21),"Working choice - awaiting review","Selected source missing")) | H21: Nigel / Manish | I21: Working comparator only; retain prior FIASA comparison pending reconciliation. | J21: Before baseline acceptance
A22: fuel_oil | B22: 2024 | C22: =IF(ISNUMBER('Evidence'!H11),'Evidence'!H11,"") | D22: =IF(ISNUMBER('Evidence'!H12),'Evidence'!H12,"") | E22: FIASA | F22: =IF(E22="FIASA",IF(ISNUMBER(C22),C22,""),IF(E22="Department",IF(ISNUMBER(D22),D22,""),"")) | G22: =IF(E22="Unresolved","No source selected",IF(ISNUMBER(F22),"Working choice - awaiting review","Selected source missing")) | H22: Nigel / Manish | I22: Working comparator only; retain prior FIASA comparison pending reconciliation. | J22: Before baseline acceptance
A23: fuel_oil | B23: 2025 | C23: =IF(ISNUMBER('Evidence'!I11),'Evidence'!I11,"") | D23: =IF(ISNUMBER('Evidence'!I12),'Evidence'!I12,"") | E23: Unresolved | F23: =IF(E23="FIASA",IF(ISNUMBER(C23),C23,""),IF(E23="Department",IF(ISNUMBER(D23),D23,""),"")) | G23: =IF(E23="Unresolved","No source selected",IF(ISNUMBER(F23),"Working choice - awaiting review","Selected source missing")) | H23: Nigel / Manish | I23: Working comparator only; retain prior FIASA comparison pending reconciliation. | J23: Before baseline acceptance
A24: fuel_oil | B24: 2026 | C24: =IF(ISNUMBER('Evidence'!J11),'Evidence'!J11,"") | D24: =IF(ISNUMBER('Evidence'!J12),'Evidence'!J12,"") | E24: Unresolved | F24: =IF(E24="FIASA",IF(ISNUMBER(C24),C24,""),IF(E24="Department",IF(ISNUMBER(D24),D24,""),"")) | G24: =IF(E24="Unresolved","No source selected",IF(ISNUMBER(F24),"Working choice - awaiting review","Selected source missing")) | H24: Nigel / Manish | I24: Working comparator only; retain prior FIASA comparison pending reconciliation. | J24: Before baseline acceptance

Sheet Methods
A1: Demand methods by segment
A2: Agree the method and geographic definition before choosing numerical ranges.
A4: Product / segment | B4: Current model | C4: Proposed direction | D4: National / provincial treatment | E4: Boundary and overlap check | F4: Evidence / workshop decision
A5: Petrol passenger | B5: National passenger/LCV/HCV cohort model; GDP/capita predicts sales. EV uptake, scrappage, km and fixed cohort efficiency determine litres. | C5: Retain cohort logic; calibrate opening stock and sales. Separate BEV, PHEV and conventional hybrid. | D5: Allocate national totals initially; local stock/activity calculations when evidence supports them. | E5: New-sales shares are not fleet shares. Apply efficiency improvements to new cohorts only. | F5: Confirm opening stock, drivetrain basis, survival and mileage. Sources: vehicles.yaml; vehicles.py.
A6: Diesel road freight | B6: Heavy-commercial diesel cohort calculation; LCV activity also includes freight and other uses. | C6: Choose fleet or tonne-km method. Separate diesel, BEV and hybrid trucks by duty cycle; sales feed cohorts, and work shares reflect mileage/payload. | D6: Define province of fuel purchase versus consumption/corridor. Registrations alone do not locate fuel use. | E6: Do not add the two methods. Deduct rail diversion once. Separate mining off-road from road trucks. | F6: Agree freight/LCV scope, truck BEV/hybrid paths, payload, empty running and charging feasibility. See Freight rows 30–45.
A7: Other road demand | B7: Passenger and LCV diesel, and LCV petrol, sit in the vehicle model. | C7: Retain class-specific calculations and identify buses/taxis explicitly where evidence allows. | D7: National control totals; documented local allocation or fleet method. | E7: Do not omit non-freight diesel when reporting national diesel demand. | F7: Clarify which vehicle classes include taxis/buses and commercial passenger services.
A8: Diesel agriculture | B8: Held baseline × (GDP/capita ratio)^elasticity. 2024 baseline 700 million L; elasticity 0.2. Both provisional. | C8: Reconciled baseline × agricultural activity ratio × relative fuel intensity. Select crops/hectares/output or subsegments. | D8: Provincial agricultural activity allocates baseline and drives changes; national total sums local results. | E8: Separate machinery, irrigation, road vehicles and backup generation. | F8: Choose source/baseline year and activity proxy; agree whether intensity already includes mechanisation.
A9: Diesel manufacturing | B9: Current combined industrial bucket includes manufacturing, mining and construction; no separate manufacturing output. | C9: Separate manufacturing baseline × production/activity × relative intensity × remaining diesel fraction. | D9: Local manufacturing/site activity where evidenced; retain unknown coverage. | E9: Separate process/equipment diesel from road freight and backup generation. Electrification is counted once. | F9: See Manufacturing. Split/revise the combined baseline explicitly and retain construction/other.
A10: Diesel generation | B10: National OCGT capacity/load factor/efficiency pathway. | C10: Plant generation × fuel per kWh; grid plants and private backup separately. | D10: Grid plants assigned by location; private backup needs an evidenced allocation. | E10: No second load-shedding increment if already in generation. Fiscal/calendar and plant coverage must match. | F10: Fit generation-to-litres; agree dispatch and private-backup evidence.
A11: Jet aviation | B11: Legacy passenger regression; movement-driver proposal awaits refit. | C11: Aircraft activity × calibrated fuel relationship including aircraft/route mix. | D11: Airport-level evidence preferred; sum airports and retain unallocated coverage. | E11: Distinguish fuel uplift from overflight/use. Cargo, non-ACSA and international scope explicit. | F11: Match movements with jet deliveries. SAF changes fossil share, not total jet litres by itself.
A12: Marine / other | B12: Held marine baseline, GDP response and product split; other uses need a coverage review. | C12: Port/vessel activity × fuel intensity or reconciled indexed baseline. | D12: Port evidence where available; unknown location remains unallocated. | E12: Define domestic versus international bunkers; diesel grade and fuel oil stay explicit. | F12: Agree coverage and identify residual demand without treating the residual as a new measured segment.
A13: Cross-cutting rule | B13: One fuel total must reconcile across all included segments. | C13: National total = provinces + explicitly unallocated demand. | D13: Use one approach per segment: allocated or locally calculated. | E13: Do not reallocate a component already calculated provincially. GDP must not multiply several overlapping effects. | F13: Source: https://github.com/Africa-International-Advisors/liquid_fuels_model/blob/8c69f8333192483f19cd80911cb90fcd0943eb6b/workstreams/WS0_governance/workplan/fuel_lever_review_2026-10-07.md
A14: Diesel mining | B14: Current combined industrial bucket; no separate mining output. | C14: Mining baseline × activity × operating intensity × remaining diesel fraction; fit sites/subsectors where possible. | D14: Mine-site geography and activity; explicit unallocated remainder. | E14: Separate mine-site/off-road work from public-road freight; backup fuel belongs to one segment. | F14: See Mining. Review commodity output versus material moved and mine-equipment electrification.

Sheet Petrol
A1: Petrol passenger demand
A2: Current national high_demand case • Values are provisional model inputs/outputs, not observed demand.
A4: Driver / output | B4: Unit | C4: Role | D4: Scalar / latest value | E4: Definition / period | F4: 2022 | G4: 2023 | H4: 2024 | I4: 2025 | J4: 2026 | K4: 2027 | L4: 2028 | M4: 2029 | N4: 2030 | O4: 2031 | P4: 2032 | Q4: 2033 | R4: 2034 | S4: 2035 | T4: Coverage / status | U4: Source | V4: Missing evidence / next action
A5: Current engine inputs
A6: GDP per capita | B6: 2015 ZAR/person | C6: Input series | E6: Shared macro driver. Model forecasts beyond the source observation window. | F6: =IF(ISNUMBER('Model run'!F5),'Model run'!F5,"") | G6: =IF(ISNUMBER('Model run'!G5),'Model run'!G5,"") | H6: =IF(ISNUMBER('Model run'!H5),'Model run'!H5,"") | I6: =IF(ISNUMBER('Model run'!I5),'Model run'!I5,"") | J6: =IF(ISNUMBER('Model run'!J5),'Model run'!J5,"") | K6: =IF(ISNUMBER('Model run'!K5),'Model run'!K5,"") | L6: =IF(ISNUMBER('Model run'!L5),'Model run'!L5,"") | M6: =IF(ISNUMBER('Model run'!M5),'Model run'!M5,"") | ... S6: =IF(ISNUMBER('Model run'!S5),'Model run'!S5,"")
A7: New-sales regression slope | B7: vehicles / ZAR pc | C7: Scalar | D7: =IF(ISNUMBER('Model run'!D6),'Model run'!D6,"") | E7: Sales = max(0, slope × GDP/capita + intercept). Applies to all new vehicles.
A8: New-sales regression intercept | B8: vehicles/year | C8: Scalar | D8: =IF(ISNUMBER('Model run'!D7),'Model run'!D7,"") | E8: Legacy fitted parameter; historical validity needs review.
A9: Passenger share of new sales | B9: share | C9: Scalar | D9: =IF(ISNUMBER('Model run'!D8),'Model run'!D8,"") | E9: Current provisional split of total modelled new sales.
A10: Petrol share of passenger ICE sales | B10: share | C10: Scalar | D10: =IF(ISNUMBER('Model run'!D9),'Model run'!D9,"") | E10: Applies after current EV adjustment. Hybrids are not separately modelled.
A11: Passenger annual mileage | B11: km/vehicle/year | C11: Scalar | D11: =IF(ISNUMBER('Model run'!D10),'Model run'!D10,"") | E11: Current placeholder. Proposed HML brackets appear on HML sheet.
A12: Passenger retirement rate | B12: share/year | C12: Scalar | D12: =IF(ISNUMBER('Model run'!D11),'Model run'!D11,"") | E12: Current engine scraps all cohorts, including additions, within the year.
A13: Base new petrol vehicle consumption | B13: L/100 km | C13: Scalar | D13: =IF(ISNUMBER('Model run'!D12),'Model run'!D12,"") | E13: Entry-cohort baseline before cumulative efficiency gains.
A14: New-cohort efficiency gain | B14: fraction/year | C14: Input series | E14: Applied cumulatively to new cohorts; older cohorts retain their… [N029] | F14: =IF(ISNUMBER('Model run'!F13),'Model run'!F13,"") | G14: =IF(ISNUMBER('Model run'!G13),'Model run'!G13,"") | H14: =IF(ISNUMBER('Model run'!H13),'Model run'!H13,"") | I14: =IF(ISNUMBER('Model run'!I13),'Model run'!I13,"") | J14: =IF(ISNUMBER('Model run'!J13),'Model run'!J13,"") | K14: =IF(ISNUMBER('Model run'!K13),'Model run'!K13,"") | L14: =IF(ISNUMBER('Model run'!L13),'Model run'!L13,"") | M14: =IF(ISNUMBER('Model run'!M13),'Model run'!M13,"") | ... S14: =IF(ISNUMBER('Model run'!S13),'Model run'!S13,"")
A15: EV curve ceiling | B15: share | C15: Parameter | D15: =IF(ISNUMBER('Model run'!D14),'Model run'!D14,"") | E15: Current logistic curve parameter. Proposed BEV sales ranges are separate.
A16: EV curve midpoint / slope | B16: year / years | C16: Parameters | E16: 2040 / 3. Confirm sales basis and replace with reviewed drivetrain paths.
A17: Current engine outputs and reporting calculations
A18: Passenger petrol fleet | B18: vehicles | C18: Engine output | E18: Cohort stock from engine diagnostics. Opening stock is… [N030] | F18: =IF(ISNUMBER('Model run'!F15),'Model run'!F15,"") | G18: =IF(ISNUMBER('Model run'!G15),'Model run'!G15,"") | H18: =IF(ISNUMBER('Model run'!H15),'Model run'!H15,"") | I18: =IF(ISNUMBER('Model run'!I15),'Model run'!I15,"") | J18: =IF(ISNUMBER('Model run'!J15),'Model run'!J15,"") | K18: =IF(ISNUMBER('Model run'!K15),'Model run'!K15,"") | L18: =IF(ISNUMBER('Model run'!L15),'Model run'!L15,"") | M18: =IF(ISNUMBER('Model run'!M15),'Model run'!M15,"") | ... S18: =IF(ISNUMBER('Model run'!S15),'Model run'!S15,"")
A19: Passenger petrol vehicle-km | B19: km/year | C19: Engine output | E19: Engine diagnostic activity for petrol passenger cohorts. | F19: =IF(ISNUMBER('Model run'!F16),'Model run'!F16,"") | G19: =IF(ISNUMBER('Model run'!G16),'Model run'!G16,"") | H19: =IF(ISNUMBER('Model run'!H16),'Model run'!H16,"") | I19: =IF(ISNUMBER('Model run'!I16),'Model run'!I16,"") | J19: =IF(ISNUMBER('Model run'!J16),'Model run'!J16,"") | K19: =IF(ISNUMBER('Model run'!K16),'Model run'!K16,"") | L19: =IF(ISNUMBER('Model run'!L16),'Model run'!L16,"") | M19: =IF(ISNUMBER('Model run'!M16),'Model run'!M16,"") | ... S19: =IF(ISNUMBER('Model run'!S16),'Model run'!S16,"")
A20: Passenger petrol demand | B20: L/year | C20: Engine output | E20: Calculated by the Python cohort engine. | F20: =IF(ISNUMBER('Model run'!F17),'Model run'!F17,"") | G20: =IF(ISNUMBER('Model run'!G17),'Model run'!G17,"") | H20: =IF(ISNUMBER('Model run'!H17),'Model run'!H17,"") | I20: =IF(ISNUMBER('Model run'!I17),'Model run'!I17,"") | J20: =IF(ISNUMBER('Model run'!J17),'Model run'!J17,"") | K20: =IF(ISNUMBER('Model run'!K17),'Model run'!K17,"") | L20: =IF(ISNUMBER('Model run'!L17),'Model run'!L17,"") | M20: =IF(ISNUMBER('Model run'!M17),'Model run'!M17,"") | ... S20: =IF(ISNUMBER('Model run'!S17),'Model run'!S17,"")
A21: Passenger petrol demand | B21: million L/year | C21: Reporting formula | E21: Unit conversion of the engine output. | F21: =F20/1000000 | G21: =G20/1000000 | H21: =H20/1000000 | I21: =I20/1000000 | J21: =J20/1000000 | K21: =K20/1000000 | L21: =L20/1000000 | M21: =M20/1000000 | ... S21: =S20/1000000
A22: Implied fleet-average consumption | B22: L/100 km | C22: Reporting formula | E22: Fuel / vehicle-km × 100. Reporting diagnostic, not new-cohort consumption. | F22: =IF(F19=0,"",F20/F19*100) | G22: =IF(G19=0,"",G20/G19*100) | H22: =IF(H19=0,"",H20/H19*100) | I22: =IF(I19=0,"",I20/I19*100) | J22: =IF(J19=0,"",J20/J19*100) | K22: =IF(K19=0,"",K20/K19*100) | L22: =IF(L19=0,"",L20/L19*100) | M22: =IF(M19=0,"",M20/M19*100) | ... S22: =IF(S19=0,"",S20/S19*100)
A23: All road petrol demand | B23: L/year | C23: Engine output | E23: Includes passenger and LCV petrol. Does not claim all-product/sector coverage. | F23: =IF(COUNT(F20,F46)<2,"",F20+F46) | G23: =IF(COUNT(G20,G46)<2,"",G20+G46) | H23: =IF(COUNT(H20,H46)<2,"",H20+H46) | I23: =IF(COUNT(I20,I46)<2,"",I20+I46) | J23: =IF(COUNT(J20,J46)<2,"",J20+J46) | K23: =IF(COUNT(K20,K46)<2,"",K20+K46) | L23: =IF(COUNT(L20,L46)<2,"",L20+L46) | M23: =IF(COUNT(M20,M46)<2,"",M20+M46) | ... S23: =IF(COUNT(S20,S46)<2,"",S20+S46)
A25: Proposed input/output rows to agree and populate
A26: New passenger sales / BEV share | B26: vehicles / share | C26: Workshop input | E26: New sales evidence is now in rows 35–41. Class-specific adoption… [N031]
A27: Verified opening fleet | B27: vehicles at date | C27: Workshop input | E27: All-drivetrain stock is in row 36. Petrol-only opening fleet and… [N032]
A28: Reported total petrol sales | B28: million L/year | C28: Staged observation | D28: =IF(ISNUMBER('Evidence'!D5),'Evidence'!D5,"") | E28: FIASA staged reported sales; latest edition selected by existing… [N033] | F28: =IF(ISNUMBER('Evidence'!F5),'Evidence'!F5,"") | G28: =IF(ISNUMBER('Evidence'!G5),'Evidence'!G5,"") | H28: =IF(ISNUMBER('Evidence'!H5),'Evidence'!H5,"") | I28: =IF(ISNUMBER('Evidence'!I5),'Evidence'!I5,"") | J28: =IF(ISNUMBER('Evidence'!J5),'Evidence'!J5,"") | K28: =IF(ISNUMBER('Evidence'!K5),'Evidence'!K5,"") | L28: =IF(ISNUMBER('Evidence'!L5),'Evidence'!L5,"") | M28: =IF(ISNUMBER('Evidence'!M5),'Evidence'!M5,"") | ... S28: =IF(ISNUMBER('Evidence'!S5),'Evidence'!S5,"") | T28: Unreviewed source extract; annual cells contain… [N034] | U28: Evidence row 5; assumptions/2026/timeseries/fuel_sales_fiasa.csv | V28: All-product comparator; compare with road total,… [N035]
A30: Source | B30: URL | C30: Source | E30: https://github.com/Africa-International-Advisors/liquid_fuels_mode… [N036]
A31: Calculation source | B31: URL | C31: Source | E31: https://github.com/Africa-International-Advisors/liquid_fuels_mode… [N037]
A32: Macro / efficiency sources | B32: URL | C32: Source | E32: https://github.com/Africa-International-Advisors/liquid_fuels_mode… [N038]
A34: Available historical evidence: separate from current engine inputs
A35: New passenger-car sales | B35: vehicles/year | C35: Staged observation | D35: =IF(ISNUMBER('Evidence'!D13),'Evidence'!D13,"") | E35: NAAMSA actual new sales. Published 2026/27 projections excluded… [N039] | F35: =IF(ISNUMBER('Evidence'!F13),'Evidence'!F13,"") | G35: =IF(ISNUMBER('Evidence'!G13),'Evidence'!G13,"") | H35: =IF(ISNUMBER('Evidence'!H13),'Evidence'!H13,"") | I35: =IF(ISNUMBER('Evidence'!I13),'Evidence'!I13,"") | J35: =IF(ISNUMBER('Evidence'!J13),'Evidence'!J13,"") | K35: =IF(ISNUMBER('Evidence'!K13),'Evidence'!K13,"") | L35: =IF(ISNUMBER('Evidence'!L13),'Evidence'!L13,"") | M35: =IF(ISNUMBER('Evidence'!M13),'Evidence'!M13,"") | ... S35: =IF(ISNUMBER('Evidence'!S13),'Evidence'!S13,"") | T35: Unreviewed source extract; annual cells contain… [N040] | U35: Evidence row 13;… [N041] | V35: G02: fit class-specific sales and compare with… [N042]
A36: Registered cars, all drivetrains | B36: vehicles | C36: Staged observation | D36: =IF(ISNUMBER('Evidence'!D20),'Evidence'!D20,"") | E36: eNaTIS December snapshots; latest June 2026 kept separately. No… [N043] | F36: =IF(ISNUMBER('Evidence'!F20),'Evidence'!F20,"") | G36: =IF(ISNUMBER('Evidence'!G20),'Evidence'!G20,"") | H36: =IF(ISNUMBER('Evidence'!H20),'Evidence'!H20,"") | I36: =IF(ISNUMBER('Evidence'!I20),'Evidence'!I20,"") | J36: =IF(ISNUMBER('Evidence'!J20),'Evidence'!J20,"") | K36: =IF(ISNUMBER('Evidence'!K20),'Evidence'!K20,"") | L36: =IF(ISNUMBER('Evidence'!L20),'Evidence'!L20,"") | M36: =IF(ISNUMBER('Evidence'!M20),'Evidence'!M20,"") | ... S36: =IF(ISNUMBER('Evidence'!S20),'Evidence'!S20,"") | T36: Unreviewed source extract; annual cells contain… [N044] | U36: Evidence row 20;… [N045] | V36: G02: obtain petrol/diesel/BEV/hybrid and age split.
A37: BEV new sales — all market | B37: vehicles/year | C37: Staged observation | D37: =IF(ISNUMBER('Evidence'!D17),'Evidence'!D17,"") | E37: All-market drivetrain sales; passenger/truck split is not… [N046] | F37: =IF(ISNUMBER('Evidence'!F17),'Evidence'!F17,"") | G37: =IF(ISNUMBER('Evidence'!G17),'Evidence'!G17,"") | H37: =IF(ISNUMBER('Evidence'!H17),'Evidence'!H17,"") | I37: =IF(ISNUMBER('Evidence'!I17),'Evidence'!I17,"") | J37: =IF(ISNUMBER('Evidence'!J17),'Evidence'!J17,"") | K37: =IF(ISNUMBER('Evidence'!K17),'Evidence'!K17,"") | L37: =IF(ISNUMBER('Evidence'!L17),'Evidence'!L17,"") | M37: =IF(ISNUMBER('Evidence'!M17),'Evidence'!M17,"") | ... S37: =IF(ISNUMBER('Evidence'!S17),'Evidence'!S17,"") | T37: Unreviewed source extract; annual cells contain… [N047] | U37: Evidence row 17;… [N048] | V37: G03: class split missing; do not treat as… [N049]
A38: PHEV new sales — all market | B38: vehicles/year | C38: Staged observation | D38: =IF(ISNUMBER('Evidence'!D18),'Evidence'!D18,"") | E38: All-market drivetrain sales; passenger/truck split is not… [N050] | F38: =IF(ISNUMBER('Evidence'!F18),'Evidence'!F18,"") | G38: =IF(ISNUMBER('Evidence'!G18),'Evidence'!G18,"") | H38: =IF(ISNUMBER('Evidence'!H18),'Evidence'!H18,"") | I38: =IF(ISNUMBER('Evidence'!I18),'Evidence'!I18,"") | J38: =IF(ISNUMBER('Evidence'!J18),'Evidence'!J18,"") | K38: =IF(ISNUMBER('Evidence'!K18),'Evidence'!K18,"") | L38: =IF(ISNUMBER('Evidence'!L18),'Evidence'!L18,"") | M38: =IF(ISNUMBER('Evidence'!M18),'Evidence'!M18,"") | ... S38: =IF(ISNUMBER('Evidence'!S18),'Evidence'!S18,"") | T38: Unreviewed source extract; annual cells contain… [N051] | U38: Evidence row 18;… [N052] | V38: G03: class split and electric-km fraction missing.
A39: Conventional hybrid new sales | B39: vehicles/year | C39: Staged observation | D39: =IF(ISNUMBER('Evidence'!D19),'Evidence'!D19,"") | E39: All-market drivetrain sales; passenger/truck split is not… [N053] | F39: =IF(ISNUMBER('Evidence'!F19),'Evidence'!F19,"") | G39: =IF(ISNUMBER('Evidence'!G19),'Evidence'!G19,"") | H39: =IF(ISNUMBER('Evidence'!H19),'Evidence'!H19,"") | I39: =IF(ISNUMBER('Evidence'!I19),'Evidence'!I19,"") | J39: =IF(ISNUMBER('Evidence'!J19),'Evidence'!J19,"") | K39: =IF(ISNUMBER('Evidence'!K19),'Evidence'!K19,"") | L39: =IF(ISNUMBER('Evidence'!L19),'Evidence'!L19,"") | M39: =IF(ISNUMBER('Evidence'!M19),'Evidence'!M19,"") | ... S39: =IF(ISNUMBER('Evidence'!S19),'Evidence'!S19,"") | T39: Unreviewed source extract; annual cells contain… [N054] | U39: Evidence row 19;… [N055] | V39: G03: source class-specific efficiency and mix.
A40: Total new-vehicle sales | B40: vehicles/year | C40: Staged observation | D40: =IF(ISNUMBER('Evidence'!D16),'Evidence'!D16,"") | E40: NAAMSA actual new sales. Published 2026/27 projections excluded… [N056] | F40: =IF(ISNUMBER('Evidence'!F16),'Evidence'!F16,"") | G40: =IF(ISNUMBER('Evidence'!G16),'Evidence'!G16,"") | H40: =IF(ISNUMBER('Evidence'!H16),'Evidence'!H16,"") | I40: =IF(ISNUMBER('Evidence'!I16),'Evidence'!I16,"") | J40: =IF(ISNUMBER('Evidence'!J16),'Evidence'!J16,"") | K40: =IF(ISNUMBER('Evidence'!K16),'Evidence'!K16,"") | L40: =IF(ISNUMBER('Evidence'!L16),'Evidence'!L16,"") | M40: =IF(ISNUMBER('Evidence'!M16),'Evidence'!M16,"") | ... S40: =IF(ISNUMBER('Evidence'!S16),'Evidence'!S16,"") | T40: Unreviewed source extract; annual cells contain… [N057] | U40: Evidence row 16;… [N058] | V40: G02/G03: same-market denominator only; reconcile… [N059]
A41: BEV share of total market sales | B41: share | C41: Reporting formula | E41: All-market share = BEV sales / total market sales. Not passenger-specific. | F41: =IF(COUNT(F37,F40)<2,"",IF(F40=0,"",F37/F40)) | G41: =IF(COUNT(G37,G40)<2,"",IF(G40=0,"",G37/G40)) | H41: =IF(COUNT(H37,H40)<2,"",IF(H40=0,"",H37/H40)) | I41: =IF(COUNT(I37,I40)<2,"",IF(I40=0,"",I37/I40)) | J41: =IF(COUNT(J37,J40)<2,"",IF(J40=0,"",J37/J40)) | K41: =IF(COUNT(K37,K40)<2,"",IF(K40=0,"",K37/K40)) | L41: =IF(COUNT(L37,L40)<2,"",IF(L40=0,"",L37/L40)) | M41: =IF(COUNT(M37,M40)<2,"",IF(M40=0,"",M37/M40)) | ... S41: =IF(COUNT(S37,S40)<2,"",IF(S40=0,"",S37/S40)) | T41: Years with both observations only. | U41: https://github.com/Africa-International-Advisors/liq… [N060] | V41: G03: obtain class-level denominator before adoption.
A42: Updated observed GDP per capita | B42: 2015 ZAR/person | C42: Staged observation | D42: =IF(ISNUMBER('Evidence'!D25),'Evidence'!D25,"") | E42: Stats SA annual actual in staged reporting copy. Sector value… [N061] | F42: =IF(ISNUMBER('Evidence'!F25),'Evidence'!F25,"") | G42: =IF(ISNUMBER('Evidence'!G25),'Evidence'!G25,"") | H42: =IF(ISNUMBER('Evidence'!H25),'Evidence'!H25,"") | I42: =IF(ISNUMBER('Evidence'!I25),'Evidence'!I25,"") | J42: =IF(ISNUMBER('Evidence'!J25),'Evidence'!J25,"") | K42: =IF(ISNUMBER('Evidence'!K25),'Evidence'!K25,"") | L42: =IF(ISNUMBER('Evidence'!L25),'Evidence'!L25,"") | M42: =IF(ISNUMBER('Evidence'!M25),'Evidence'!M25,"") | ... S42: =IF(ISNUMBER('Evidence'!S25),'Evidence'!S25,"") | T42: Unreviewed source extract; annual cells contain… [N062] | U42: Evidence row 25;… [N063] | V42: G02: reconcile updated series against engine macro assumptions.
A44: LCV petrol stock | B44: vehicles | C44: Linked model output | E44: Model run row 54; Python vehicle cohort result. | F44: =IF(ISNUMBER('Model run'!F54),'Model run'!F54,"") | G44: =IF(ISNUMBER('Model run'!G54),'Model run'!G54,"") | H44: =IF(ISNUMBER('Model run'!H54),'Model run'!H54,"") | I44: =IF(ISNUMBER('Model run'!I54),'Model run'!I54,"") | J44: =IF(ISNUMBER('Model run'!J54),'Model run'!J54,"") | K44: =IF(ISNUMBER('Model run'!K54),'Model run'!K54,"") | L44: =IF(ISNUMBER('Model run'!L54),'Model run'!L54,"") | M44: =IF(ISNUMBER('Model run'!M54),'Model run'!M54,"") | ... S44: =IF(ISNUMBER('Model run'!S54),'Model run'!S54,"")
A45: LCV petrol vehicle kilometres | B45: vehicle km/year | C45: Linked model output | E45: Model run row 55; Python vehicle cohort result. | F45: =IF(ISNUMBER('Model run'!F55),'Model run'!F55,"") | G45: =IF(ISNUMBER('Model run'!G55),'Model run'!G55,"") | H45: =IF(ISNUMBER('Model run'!H55),'Model run'!H55,"") | I45: =IF(ISNUMBER('Model run'!I55),'Model run'!I55,"") | J45: =IF(ISNUMBER('Model run'!J55),'Model run'!J55,"") | K45: =IF(ISNUMBER('Model run'!K55),'Model run'!K55,"") | L45: =IF(ISNUMBER('Model run'!L55),'Model run'!L55,"") | M45: =IF(ISNUMBER('Model run'!M55),'Model run'!M55,"") | ... S45: =IF(ISNUMBER('Model run'!S55),'Model run'!S55,"")
...

Sheet Freight
A1: Diesel road freight demand
A2: Current national heavy-commercial example • Heavy trucks are only part of road-freight demand.
A4: Driver / output | B4: Unit | C4: Role | D4: Scalar / latest value | E4: Definition / period | F4: 2022 | G4: 2023 | H4: 2024 | I4: 2025 | J4: 2026 | K4: 2027 | L4: 2028 | M4: 2029 | N4: 2030 | O4: 2031 | P4: 2032 | Q4: 2033 | R4: 2034 | S4: 2035 | T4: Coverage / status | U4: Source | V4: Missing evidence / next action
A5: Current fleet-method inputs
A6: GDP per capita | B6: 2015 ZAR/person | C6: Input series | E6: Same national vehicle-sales regression as Petrol sheet. | F6: =IF(ISNUMBER('Model run'!F19),'Model run'!F19,"") | G6: =IF(ISNUMBER('Model run'!G19),'Model run'!G19,"") | H6: =IF(ISNUMBER('Model run'!H19),'Model run'!H19,"") | I6: =IF(ISNUMBER('Model run'!I19),'Model run'!I19,"") | J6: =IF(ISNUMBER('Model run'!J19),'Model run'!J19,"") | K6: =IF(ISNUMBER('Model run'!K19),'Model run'!K19,"") | L6: =IF(ISNUMBER('Model run'!L19),'Model run'!L19,"") | M6: =IF(ISNUMBER('Model run'!M19),'Model run'!M19,"") | ... S6: =IF(ISNUMBER('Model run'!S19),'Model run'!S19,"")
A7: HCV share of new vehicle sales | B7: share | C7: Scalar | D7: =IF(ISNUMBER('Model run'!D20),'Model run'!D20,"") | E7: Current provisional class split.
A8: Diesel share of HCV ICE sales | B8: share | C8: Scalar | D8: =IF(ISNUMBER('Model run'!D21),'Model run'!D21,"") | E8: Current model applies its common EV adjustment before the diesel split.
A9: Heavy-truck annual mileage | B9: km/vehicle/year | C9: Scalar | D9: =IF(ISNUMBER('Model run'!D22),'Model run'!D22,"") | E9: Current provisional assumption.
A10: Heavy-truck retirement rate | B10: share/year | C10: Scalar | D10: =IF(ISNUMBER('Model run'!D23),'Model run'!D23,"") | E10: Flat retirement assumption across cohorts.
A11: Base new-truck consumption | B11: L/100 km | C11: Scalar | D11: =IF(ISNUMBER('Model run'!D24),'Model run'!D24,"") | E11: Entry-cohort baseline before efficiency improvement.
A12: New-cohort efficiency gain | B12: fraction/year | C12: Input series | E12: Applies to new cohorts only. | F12: =IF(ISNUMBER('Model run'!F25),'Model run'!F25,"") | G12: =IF(ISNUMBER('Model run'!G25),'Model run'!G25,"") | H12: =IF(ISNUMBER('Model run'!H25),'Model run'!H25,"") | I12: =IF(ISNUMBER('Model run'!I25),'Model run'!I25,"") | J12: =IF(ISNUMBER('Model run'!J25),'Model run'!J25,"") | K12: =IF(ISNUMBER('Model run'!K25),'Model run'!K25,"") | L12: =IF(ISNUMBER('Model run'!L25),'Model run'!L25,"") | M12: =IF(ISNUMBER('Model run'!M25),'Model run'!M25,"") | ... S12: =IF(ISNUMBER('Model run'!S25),'Model run'!S25,"")
A14: Current engine outputs and reporting calculations
A15: Heavy-truck diesel fleet | B15: vehicles | C15: Engine output | E15: National HCV diesel cohort stock. | F15: =IF(ISNUMBER('Model run'!F26),'Model run'!F26,"") | G15: =IF(ISNUMBER('Model run'!G26),'Model run'!G26,"") | H15: =IF(ISNUMBER('Model run'!H26),'Model run'!H26,"") | I15: =IF(ISNUMBER('Model run'!I26),'Model run'!I26,"") | J15: =IF(ISNUMBER('Model run'!J26),'Model run'!J26,"") | K15: =IF(ISNUMBER('Model run'!K26),'Model run'!K26,"") | L15: =IF(ISNUMBER('Model run'!L26),'Model run'!L26,"") | M15: =IF(ISNUMBER('Model run'!M26),'Model run'!M26,"") | ... S15: =IF(ISNUMBER('Model run'!S26),'Model run'!S26,"")
A16: Heavy-truck vehicle-km | B16: km/year | C16: Engine output | E16: National HCV diesel activity. | F16: =IF(ISNUMBER('Model run'!F27),'Model run'!F27,"") | G16: =IF(ISNUMBER('Model run'!G27),'Model run'!G27,"") | H16: =IF(ISNUMBER('Model run'!H27),'Model run'!H27,"") | I16: =IF(ISNUMBER('Model run'!I27),'Model run'!I27,"") | J16: =IF(ISNUMBER('Model run'!J27),'Model run'!J27,"") | K16: =IF(ISNUMBER('Model run'!K27),'Model run'!K27,"") | L16: =IF(ISNUMBER('Model run'!L27),'Model run'!L27,"") | M16: =IF(ISNUMBER('Model run'!M27),'Model run'!M27,"") | ... S16: =IF(ISNUMBER('Model run'!S27),'Model run'!S27,"")
A17: Heavy-truck diesel demand | B17: L/year | C17: Engine output | E17: Current Python engine output. Does not include LCV freight. | F17: =IF(ISNUMBER('Model run'!F28),'Model run'!F28,"") | G17: =IF(ISNUMBER('Model run'!G28),'Model run'!G28,"") | H17: =IF(ISNUMBER('Model run'!H28),'Model run'!H28,"") | I17: =IF(ISNUMBER('Model run'!I28),'Model run'!I28,"") | J17: =IF(ISNUMBER('Model run'!J28),'Model run'!J28,"") | K17: =IF(ISNUMBER('Model run'!K28),'Model run'!K28,"") | L17: =IF(ISNUMBER('Model run'!L28),'Model run'!L28,"") | M17: =IF(ISNUMBER('Model run'!M28),'Model run'!M28,"") | ... S17: =IF(ISNUMBER('Model run'!S28),'Model run'!S28,"")
A18: Heavy-truck diesel demand | B18: million L/year | C18: Reporting formula | E18: Unit conversion of engine output. | F18: =F17/1000000 | G18: =G17/1000000 | H18: =H17/1000000 | I18: =I17/1000000 | J18: =J17/1000000 | K18: =K17/1000000 | L18: =L17/1000000 | M18: =M17/1000000 | ... S18: =S17/1000000
A19: Implied fleet-average consumption | B19: L/100 km | C19: Reporting formula | E19: Fuel / vehicle-km × 100. | F19: =IF(F16=0,"",F17/F16*100) | G19: =IF(G16=0,"",G17/G16*100) | H19: =IF(H16=0,"",H17/H16*100) | I19: =IF(I16=0,"",I17/I16*100) | J19: =IF(J16=0,"",J17/J16*100) | K19: =IF(K16=0,"",K17/K16*100) | L19: =IF(L16=0,"",L17/L16*100) | M19: =IF(M16=0,"",M17/M16*100) | ... S19: =IF(S16=0,"",S17/S16*100)
A21: Alternative tonne-km method: agree before implementation
A22: Reference road freight activity | B22: tonne-km/year | C22: Workshop input | E22: Choose eligible road work before rail diversion; tonnes alone omit distance.
A23: Road work diverted to rail | B23: share of reference | C23: Workshop input | E23: Deduct once. If already reflected in the road activity path, do… [N064]
A24: Freight fuel intensity | B24: L/tonne-km | C24: Workshop input | E24: Calibrate to payload, empty running and vehicle mix.
A25: Alternative freight demand | B25: million L/year | C25: Proposed output | E25: Reference tonne-km × (1 − eligible diversion share) × L/tonne-km… [N065]
A26: Geographic definition | B26: decision | C26: Workshop input | E26: Agree fuel sales location versus consumption/corridor. Do not… [N066]
A28: Source | B28: URL | C28: Source | E28: https://github.com/Africa-International-Advisors/liquid_fuels_mode… [N067]
A30: Freight electrification: current setting and proposed replacement
A31: Current common EV share of new sales | B31: share | C31: Engine output | E31: Existing engine curve applied to HCV as well as other classes.… [N068] | F31: =IF(ISNUMBER('Model run'!F29),'Model run'!F29,"") | G31: =IF(ISNUMBER('Model run'!G29),'Model run'!G29,"") | H31: =IF(ISNUMBER('Model run'!H29),'Model run'!H29,"") | I31: =IF(ISNUMBER('Model run'!I29),'Model run'!I29,"") | J31: =IF(ISNUMBER('Model run'!J29),'Model run'!J29,"") | K31: =IF(ISNUMBER('Model run'!K29),'Model run'!K29,"") | L31: =IF(ISNUMBER('Model run'!L29),'Model run'!L29,"") | M31: =IF(ISNUMBER('Model run'!M29),'Model run'!M29,"") | ... S31: =IF(ISNUMBER('Model run'!S29),'Model run'!S29,"")
A32: Truck BEV share of new sales | B32: share | C32: Workshop input | E32: Separate light delivery, regional and long-haul cohorts. Use… [N069]
A33: Truck hybrid / PHEV new-sales share | B33: share | C33: Workshop input | E33: Separate from BEVs. Record residual diesel use; PHEV… [N070]
A34: Opening fleet and survival by drivetrain | B34: vehicles / survival | C34: Workshop input | E34: New-sales shares become stock through cohort additions and… [N071]
A35: Mileage by drivetrain / duty cycle | B35: km/vehicle/year | C35: Workshop input | E35: Electric and diesel trucks can perform different annual work. Use… [N072]
