Workbook

Sheet Contents
A1: Master data book: sourced data for the South Africa story
A2: The one place to look for a sourced figure, set out by data request (DR01, DR04, DR07, DR08). Petrol and diesel only. Every figure names its source. Built by python -m lfm.scripts.build_data_requests_workbook --vintage 2026; do not edit by hand.
A4: Sheet | B4: What it holds | C4: From source | D4: Calculated | E4: Not available
A5: DR01 national balance | B5: Sales, production, imports and exports by year, with the difference between supply and sales | C5: 8 | D5: 2 | E5: 2
A6: DR01 sales by province | B6: Petrol and diesel sold in each of the nine provinces by year; 2023 estimated
A7: DR01 demand by sector | B7: Diesel and petrol used by industry, mining, agriculture, transport and other sectors, 2014 to 2021
A8: DR01 sector activity | B8: Mining, manufacturing and agriculture: activity to 2025, diesel per unit of activity, and estimated diesel after 2021
A9: DR04 routes and access | B9: Pipeline limit and cost, regulated and published transport costs, port use, access at Durban and Lesedi, competing routes | C9: 66 | D9: 6 | E9: 7
A10: DR04 entry points | B10: Petrol and diesel imports cleared at each customs office, by year
A11: DR04 transport cost | B11: The Durban to Gauteng route by cost element, and the regulated transport differential for all 54 pricing zones
A12: DR07 demand evidence | B12: Eskom and independent diesel burn, plant dates, vehicle fleet, new vehicles, efficiency, freight and rail | C12: 75 | D12: 21 | E12: 5
A13: DR07 fleet by province | B13: Registered vehicles by class and province, and petrol and diesel vehicles by province
A14: DR08 refinery supply | B14: Capacity, status and closure dates, output by plant and nationally, yields, utilisation and outlook | C14: 43 | D14: 19 | E14: 2
A15: Market sizing | B15: What Vopak Durban and Vopak Lesedi can reach: site markets, the inland-bound flow, the trunk line and what the tanks allow
A16: Not available | B16: The 17 items that could not be found, with the reason for each
A18: Colours
A19: Blue: read from a published source
A20: White: calculated here from figures on the sheet
A21: Yellow: not available

Sheet DR01 national balance
A1: DR01 National balance: petrol and diesel
A2: Billion litres, calendar years. Blank means not published. Sales are the department's figures: provinces added up for 2014 to 2022, the national total for 2023. FIASA and JODI are not used.
A5: Petrol
A6: Line | B6: 2014 | C6: 2015 | D6: 2016 | E6: 2017 | F6: 2018 | G6: 2019 | H6: 2020 | I6: 2021 | J6: 2022 | K6: 2023 | L6: 2024 | M6: 2025 | N6: Source | O6: Note
A7: Sales | B7: 11.030665 | C7: 11.469654 | D7: 11.462252 | E7: 11.173811 | F7: 10.928999 | G7: 10.773208 | H7: 8.761471 | I7: 9.3015842 | J7: 9.1848699 | K7: 9.0369501 | N7: Department of Mineral and Petroleum Resources, fuel sales volumes | O7: Nothing published after 2023.
A8: Production | B8: 10.82816 | C8: 10.457813 | D8: 10.393066 | E8: 9.43444 | F8: 9.97456 | G8: 10.424467 | H8: 7.895 | I8: 6.3513067 | N8: Department of Mineral and Petroleum Resources, energy balances, one file a year | O8: The last balance published is 2021.
A9: Imports | B9: 1.1501948 | C9: 1.8696452 | D9: 1.3956385 | E9: 2.1141565 | F9: 1.8297713 | G9: 1.4773858 | H9: 1.7196731 | I9: 4.0086128 | J9: 5.4552618 | K9: 4.4827748 | L9: 4.0008544 | M9: 4.4534712 | N9: SARS customs, trade statistics portal, petrol and diesel tariff lines | O9: Complete calendar years, in litres.
A10: Exports | B10: 0.98951589 | C10: 1.0856704 | D10: 1.1573288 | E10: 1.0758862 | F10: 1.1350503 | G10: 1.1747018 | H10: 1.1547791 | I10: 1.0524951 | J10: 0.85461371 | K10: 0.99401956 | L10: 0.91974502 | M10: 0.80176247 | N10: SARS customs, trade statistics portal, petrol and diesel tariff lines
A11: Stock change | N11: None | O11: Not published by any source used.
A12: Supply less sales | B12: =IF(COUNT(B7,B8,B9,B10)<4,"",B8+B9-B10-B7) | C12: =IF(COUNT(C7,C8,C9,C10)<4,"",C8+C9-C10-C7) | D12: =IF(COUNT(D7,D8,D9,D10)<4,"",D8+D9-D10-D7) | E12: =IF(COUNT(E7,E8,E9,E10)<4,"",E8+E9-E10-E7) | F12: =IF(COUNT(F7,F8,F9,F10)<4,"",F8+F9-F10-F7) | G12: =IF(COUNT(G7,G8,G9,G10)<4,"",G8+G9-G10-G7) | H12: =IF(COUNT(H7,H8,H9,H10)<4,"",H8+H9-H10-H7) | I12: =IF(COUNT(I7,I8,I9,I10)<4,"",I8+I9-I10-I7) | ... M12: =IF(COUNT(M7,M8,M9,M10)<4,"",M8+M9-M10-M7) | N12: Calculated: production + imports - exports - sales | O12: Stock change and statistical difference together. Shown only where all four lines exist.
A14: Diesel
A15: Line | B15: 2014 | C15: 2015 | D15: 2016 | E15: 2017 | F15: 2018 | G15: 2019 | H15: 2020 | I15: 2021 | J15: 2022 | K15: 2023 | L15: 2024 | M15: 2025 | N15: Source | O15: Note
A16: Sales | B16: 12.74339 | C16: 13.492151 | D16: 12.082374 | E16: 12.14515 | F16: 12.31862 | G16: 12.908631 | H16: 11.689958 | I16: 12.945018 | J16: 12.717326 | K16: 12.9075 | N16: Department of Mineral and Petroleum Resources, fuel sales volumes | O16: Nothing published after 2023.
A17: Production | B17: 9.58774 | C17: 9.368482 | D17: 9.01419 | E17: 7.921726 | F17: 8.425262 | G17: 9.080357 | H17: 6.4478095 | I17: 5.3149643 | N17: Department of Mineral and Petroleum Resources, energy balances, one file a year | O17: The last balance published is 2021.
A18: Imports | B18: 4.9917123 | C18: 6.450779 | D18: 4.424295 | E18: 6.0374599 | F18: 5.1229595 | G18: 5.5902721 | H18: 6.8149854 | I18: 9.7613953 | J18: 11.954257 | K18: 12.870032 | L18: 10.792547 | M18: 12.24872 | N18: SARS customs, trade statistics portal, petrol and diesel tariff lines | O18: Complete calendar years, in litres.
A19: Exports | B19: 1.4937626 | C19: 1.612855 | D19: 1.8856054 | E19: 1.7826741 | F19: 1.5820701 | G19: 1.7413773 | H19: 0.91381452 | I19: 0.89348811 | J19: 0.88919907 | K19: 0.88944591 | L19: 0.79583468 | M19: 0.74670021 | N19: SARS customs, trade statistics portal, petrol and diesel tariff lines
A20: Stock change | N20: None | O20: Not published by any source used.
A21: Supply less sales | B21: =IF(COUNT(B16,B17,B18,B19)<4,"",B17+B18-B19-B16) | C21: =IF(COUNT(C16,C17,C18,C19)<4,"",C17+C18-C19-C16) | D21: =IF(COUNT(D16,D17,D18,D19)<4,"",D17+D18-D19-D16) | E21: =IF(COUNT(E16,E17,E18,E19)<4,"",E17+E18-E19-E16) | F21: =IF(COUNT(F16,F17,F18,F19)<4,"",F17+F18-F19-F16) | G21: =IF(COUNT(G16,G17,G18,G19)<4,"",G17+G18-G19-G16) | H21: =IF(COUNT(H16,H17,H18,H19)<4,"",H17+H18-H19-H16) | I21: =IF(COUNT(I16,I17,I18,I19)<4,"",I17+I18-I19-I16) | ... M21: =IF(COUNT(M16,M17,M18,M19)<4,"",M17+M18-M19-M16) | N21: Calculated: production + imports - exports - sales | O21: Stock change and statistical difference together. Shown only where all four lines exist.

Sheet DR01 sales by province
A1: DR01 Sales by province: petrol and diesel
A2: Billion litres, calendar years. 2013 to 2022 are the department's district data added up by province (blue). 2023 is an estimate (yellow): the national total split by each province's share of sales in the first quarter of 2023. 2024 and 2025 are blank.
A5: Petrol
A6: Province | B6: 2013 | C6: 2014 | D6: 2015 | E6: 2016 | F6: 2017 | G6: 2018 | H6: 2019 | I6: 2020 | J6: 2021 | K6: 2022 | L6: 2023 | M6: 2024 | N6: 2025 | O6: Source | P6: Note
A7: Gauteng | B7: 4.1719835 | C7: 3.9799971 | D7: 4.1193667 | E7: 4.1769778 | F7: 4.0884051 | G7: 3.997042 | H7: 4.0762446 | I7: 3.1350668 | J7: 3.4408174 | K7: 3.5304403 | L7: 3.460323 | O7: Department of Mineral and Petroleum Resources, fuel sales volumes by magisterial district | P7: 2023 is an estimate. Nothing published by province after the first quarter of 2023.
A8: KwaZulu-Natal | B8: 1.812812 | C8: 1.7208025 | D8: 1.787553 | E8: 1.7656762 | F8: 1.725656 | G8: 1.6319803 | H8: 1.6784933 | I8: 1.44837 | J8: 1.5499221 | K8: 1.4989379 | L8: 1.457735 | O8: Department of Mineral and Petroleum Resources, fuel sales volumes by magisterial district | P8: 2023 is an estimate. Nothing published by province after the first quarter of 2023.
A9: Western Cape | B9: 1.7238819 | C9: 1.7211272 | D9: 1.7454482 | E9: 1.8251998 | F9: 1.7730428 | G9: 1.693799 | H9: 1.6579981 | I9: 1.3074771 | J9: 1.4017429 | K9: 1.4310055 | L9: 1.4654567 | O9: Department of Mineral and Petroleum Resources, fuel sales volumes by magisterial district | P9: 2023 is an estimate. Nothing published by province after the first quarter of 2023.
A10: Eastern Cape | B10: 0.80377468 | C10: 0.81949159 | D10: 0.8698725 | E10: 0.85774124 | F10: 0.83168812 | G10: 0.8097137 | H10: 0.7931128 | I10: 0.67880191 | J10: 0.73478996 | K10: 0.70313244 | L10: 0.67878638 | O10: Department of Mineral and Petroleum Resources, fuel sales volumes by magisterial district | P10: 2023 is an estimate. Nothing published by province after the first quarter of 2023.
A11: Mpumalanga | B11: 0.83170021 | C11: 0.82786684 | D11: 0.955039 | E11: 1.0293943 | F11: 0.96278017 | G11: 0.87995514 | H11: 0.80157411 | I11: 0.69051116 | J11: 0.66162121 | K11: 0.61226565 | L11: 0.63759045 | O11: Department of Mineral and Petroleum Resources, fuel sales volumes by magisterial district | P11: 2023 is an estimate. Nothing published by province after the first quarter of 2023.
A12: Free State | B12: 0.96696948 | C12: 0.93672123 | D12: 0.92128759 | E12: 0.81479378 | F12: 0.81397095 | G12: 0.97062487 | H12: 0.82469139 | I12: 0.72409523 | J12: 0.69469561 | K12: 0.58745801 | L12: 0.53608626 | O12: Department of Mineral and Petroleum Resources, fuel sales volumes by magisterial district | P12: 2023 is an estimate. Nothing published by province after the first quarter of 2023.
A13: North West | B13: 0.60384079 | C13: 0.52100824 | D13: 0.52980649 | E13: 0.51443739 | F13: 0.51414322 | G13: 0.47770129 | H13: 0.48890772 | I13: 0.41178136 | J13: 0.44521786 | K13: 0.44815623 | L13: 0.43076315 | O13: Department of Mineral and Petroleum Resources, fuel sales volumes by magisterial district | P13: 2023 is an estimate. Nothing published by province after the first quarter of 2023.
A14: Limpopo | B14: 0.40318783 | C14: 0.38240065 | D14: 0.4104566 | E14: 0.35719249 | F14: 0.35579367 | G14: 0.36657194 | H14: 0.35005766 | I14: 0.27651209 | J14: 0.27641706 | K14: 0.27364405 | L14: 0.2719085 | O14: Department of Mineral and Petroleum Resources, fuel sales volumes by magisterial district | P14: 2023 is an estimate. Nothing published by province after the first quarter of 2023.
A15: Northern Cape | B15: 0.12196366 | C15: 0.12124953 | D15: 0.13082437 | E15: 0.12083944 | F15: 0.10833104 | G15: 0.10161097 | H15: 0.10212831 | I15: 0.088855296 | J15: 0.096360077 | K15: 0.099829929 | L15: 0.098300729 | O15: Department of Mineral and Petroleum Resources, fuel sales volumes by magisterial district | P15: 2023 is an estimate. Nothing published by province after the first quarter of 2023.
A16: Nine provinces | B16: =IF(COUNT(B7:B15)=0,"",SUM(B7:B15)) | C16: =IF(COUNT(C7:C15)=0,"",SUM(C7:C15)) | D16: =IF(COUNT(D7:D15)=0,"",SUM(D7:D15)) | E16: =IF(COUNT(E7:E15)=0,"",SUM(E7:E15)) | F16: =IF(COUNT(F7:F15)=0,"",SUM(F7:F15)) | G16: =IF(COUNT(G7:G15)=0,"",SUM(G7:G15)) | H16: =IF(COUNT(H7:H15)=0,"",SUM(H7:H15)) | I16: =IF(COUNT(I7:I15)=0,"",SUM(I7:I15)) | ... N16: =IF(COUNT(N7:N15)=0,"",SUM(N7:N15)) | O16: Calculated: sum of the rows above | P16: The sales line on the national balance sheet.
A17: National file, for comparison | B17: 11.439925 | C17: 10.890208 | D17: 11.475709 | E17: 11.462252 | F17: 11.174083 | G17: 11.141631 | H17: 10.773208 | I17: 8.761471 | J17: 9.3015842 | K17: 9.1848699 | L17: 9.0369501 | O17: Department of Mineral and Petroleum Resources, national fuel sales volumes | P17: The 2023 estimates add up to this by construction. The two files differ in 2014 and 2018.
A19: Diesel
A20: Province | B20: 2013 | C20: 2014 | D20: 2015 | E20: 2016 | F20: 2017 | G20: 2018 | H20: 2019 | I20: 2020 | J20: 2021 | K20: 2022 | L20: 2023 | M20: 2024 | N20: 2025 | O20: Source | P20: Note
A21: Gauteng | B21: 2.7854298 | C21: 3.118078 | D21: 3.1604269 | E21: 2.9533257 | F21: 3.1255234 | G21: 3.3200433 | H21: 3.565209 | I21: 2.9506708 | J21: 3.2051913 | K21: 3.2789905 | L21: 3.3502336 | O21: Department of Mineral and Petroleum Resources, fuel sales volumes by magisterial district | P21: 2023 is an estimate. Nothing published by province after the first quarter of 2023.
A22: KwaZulu-Natal | B22: 2.2521565 | C22: 2.1312562 | D22: 2.1250067 | E22: 2.1768973 | F22: 2.4597014 | G22: 2.374694 | H22: 2.5760354 | I22: 2.6103203 | J22: 2.7244225 | K22: 2.7855548 | L22: 2.4505852 | O22: Department of Mineral and Petroleum Resources, fuel sales volumes by magisterial district | P22: 2023 is an estimate. Nothing published by province after the first quarter of 2023.
A23: Western Cape | B23: 1.9875328 | C23: 2.3716273 | D23: 2.9510171 | E23: 1.8960105 | F23: 1.8542224 | G23: 1.8495607 | H23: 2.0618367 | I23: 1.8494091 | J23: 2.6083712 | K23: 2.4997695 | L23: 3.031414 | O23: Department of Mineral and Petroleum Resources, fuel sales volumes by magisterial district | P23: 2023 is an estimate. Nothing published by province after the first quarter of 2023.
A24: Eastern Cape | B24: 0.78214884 | C24: 0.80722424 | D24: 0.92926903 | E24: 0.92814183 | F24: 0.93732341 | G24: 0.96060541 | H24: 0.99903178 | I24: 0.93681699 | J24: 1.0364548 | K24: 1.0323522 | L24: 1.0184892 | O24: Department of Mineral and Petroleum Resources, fuel sales volumes by magisterial district | P24: 2023 is an estimate. Nothing published by province after the first quarter of 2023.
A25: Mpumalanga | B25: 1.4888311 | C25: 1.5133165 | D25: 1.4993294 | E25: 1.6312066 | F25: 1.5460486 | G25: 1.5766914 | H25: 1.4351283 | I25: 1.3074244 | J25: 1.2756094 | K25: 1.1449241 | L25: 1.1815546 | O25: Department of Mineral and Petroleum Resources, fuel sales volumes by magisterial district | P25: 2023 is an estimate. Nothing published by province after the first quarter of 2023.
A26: Free State | B26: 1.2925251 | C26: 1.2491798 | D26: 1.2590152 | E26: 1.1249072 | F26: 0.93016393 | G26: 1.0072792 | H26: 1.0590539 | I26: 1.0305888 | J26: 1.0256523 | K26: 0.78186116 | L26: 0.70041229 | O26: Department of Mineral and Petroleum Resources, fuel sales volumes by magisterial district | P26: 2023 is an estimate. Nothing published by province after the first quarter of 2023.
A27: North West | B27: 0.66259176 | C27: 0.63727812 | D27: 0.65900795 | E27: 0.65041846 | F27: 0.58716232 | G27: 0.51402503 | H27: 0.51835939 | I27: 0.4361658 | J27: 0.50040565 | K27: 0.61990649 | L27: 0.56858027 | O27: Department of Mineral and Petroleum Resources, fuel sales volumes by magisterial district | P27: 2023 is an estimate. Nothing published by province after the first quarter of 2023.
A28: Limpopo | B28: 0.42448303 | C28: 0.40841603 | D28: 0.3712796 | E28: 0.30922616 | F28: 0.27471398 | G28: 0.2956001 | H28: 0.26969798 | I28: 0.216124 | J28: 0.21025773 | K28: 0.22198744 | L28: 0.24381457 | O28: Department of Mineral and Petroleum Resources, fuel sales volumes by magisterial district | P28: 2023 is an estimate. Nothing published by province after the first quarter of 2023.
A29: Northern Cape | B29: 0.46534822 | C29: 0.50701367 | D29: 0.53779946 | E29: 0.4122403 | F29: 0.43029076 | G29: 0.42012136 | H29: 0.4242787 | I29: 0.35243756 | J29: 0.35865318 | K29: 0.35198012 | L29: 0.36241629 | O29: Department of Mineral and Petroleum Resources, fuel sales volumes by magisterial district | P29: 2023 is an estimate. Nothing published by province after the first quarter of 2023.
A30: Nine provinces | B30: =IF(COUNT(B21:B29)=0,"",SUM(B21:B29)) | C30: =IF(COUNT(C21:C29)=0,"",SUM(C21:C29)) | D30: =IF(COUNT(D21:D29)=0,"",SUM(D21:D29)) | E30: =IF(COUNT(E21:E29)=0,"",SUM(E21:E29)) | F30: =IF(COUNT(F21:F29)=0,"",SUM(F21:F29)) | G30: =IF(COUNT(G21:G29)=0,"",SUM(G21:G29)) | H30: =IF(COUNT(H21:H29)=0,"",SUM(H21:H29)) | I30: =IF(COUNT(I21:I29)=0,"",SUM(I21:I29)) | ... N30: =IF(COUNT(N21:N29)=0,"",SUM(N21:N29)) | O30: Calculated: sum of the rows above | P30: The sales line on the national balance sheet.
A31: National file, for comparison | B31: 12.141282 | C31: 12.615023 | D31: 13.520139 | E31: 12.082374 | F31: 12.147245 | G31: 12.538744 | H31: 12.908631 | I31: 11.689958 | J31: 12.945783 | K31: 12.717326 | L31: 12.9075 | O31: Department of Mineral and Petroleum Resources, national fuel sales volumes | P31: The 2023 estimates add up to this by construction. The two files differ in 2014 and 2018.
A33: 2024 and 2025 are blank: the department has published no sales after 2023. FIASA and JODI carry figures for those years, but they are not used.

Sheet DR01 demand by sector
A1: DR01 Demand by sector: diesel and petrol
A2: Billion litres, calendar years, as reported in the department's energy balances. The last balance is 2021, so nothing later is published by sector. Blank means the balance gives no figure.
A5: Diesel
A6: Sector | B6: 2014 | C6: 2015 | D6: 2016 | E6: 2017 | F6: 2018 | G6: 2019 | H6: 2020 | I6: 2021 | J6: Source | K6: Note
A7: All sectors | B7: 12.597876 | C7: 13.49109 | D7: 12.794349 | E7: 13.258459 | F7: 13.204751 | G7: 13.535823 | H7: 12.179677 | I7: 13.407266 | J7: Department of Mineral and Petroleum Resources, energy balances, one file a year | K7: The department's total for all sectors. It is not the sales figure on the national balance sheet.
A8: Road transport | B8: 8.903131 | C8: 9.428381 | D8: 4.3963865 | E8: 9.359175 | F8: 6.3919425 | G8: 6.725982 | H8: 5.8481915 | I8: 6.3279573 | J8: Department of Mineral and Petroleum Resources, energy balances, one file a year
A9: Rail | B9: 0.09044075 | C9: 0.12395326 | D9: 0.18690598 | E9: 0.13610452 | F9: 0.16974334 | G9: 0.12818266 | H9: 0.099427187 | I9: 0.01312792 | J9: Department of Mineral and Petroleum Resources, energy balances, one file a year
A10: Industry, all | B10: 1.6397506 | C10: 1.9331292 | D10: 1.3197982 | E10: 1.5438398 | F10: 1.8844217 | G10: 1.8979908 | H10: 1.4462207 | I10: 1.4991393 | J10: Department of Mineral and Petroleum Resources, energy balances, one file a year | K10: Mining, construction, manufacturing and industry not specified, together. Manufacturing and other industry is this line less the two below.
A11: Mining (part of industry) | B11: 1.5050322 | C11: 1.8183965 | D11: 1.0442531 | E11: 1.300426 | F11: 1.650123 | G11: 1.6672493 | H11: 1.2634057 | I11: 1.2938134 | J11: Department of Mineral and Petroleum Resources, energy balances, one file a year
A12: Construction (part of industry) | B12: 0.13471839 | C12: 0.11473268 | D12: 0.13869362 | E12: 0.12446979 | F12: 0.074592859 | H12: 0.042847406 | I12: 0.04869243 | J12: Department of Mineral and Petroleum Resources, energy balances, one file a year
A13: Agriculture | B13: 1.0924988 | C13: 1.0734942 | D13: 1.8872789 | E13: 1.876914 | F13: 0.89988344 | G13: 0.92184869 | H13: 1.0489635 | I13: 1.0583989 | J13: Department of Mineral and Petroleum Resources, energy balances, one file a year
A14: Commercial and public services | B14: 0.023462721 | C14: 0.014730648 | D14: 4.9728395 | F14: 3.8237085 | G14: 3.8215455 | H14: 3.6391218 | I14: 4.2999757 | J14: Department of Mineral and Petroleum Resources, energy balances, one file a year | K14: Jumps from almost nothing to several billion litres from 2016: the department moved volumes between sectors, so read with care.
A15: Households | B15: 0.0076144878 | C15: 0.0055073389 | E15: 0.00030523999 | F15: 0.001321481 | G15: 0.00071392102 | H15: 0.0060975581 | I15: 0.00201032 | J15: Department of Mineral and Petroleum Resources, energy balances, one file a year
A16: Power stations | B16: 1.1785999 | C16: 1.2478 | D16: 1.2478001 | E16: 0.01 | F16: 0.01 | G16: 0.028724191 | J16: Department of Mineral and Petroleum Resources, energy balances, one file a year | K16: The balances record little or none after 2016; Eskom's own reported fuel is on the DR07 sheet.
A18: Petrol
A19: Sector | B19: 2014 | C19: 2015 | D19: 2016 | E19: 2017 | F19: 2018 | G19: 2019 | H19: 2020 | I19: 2021 | J19: Source | K19: Note
A20: All sectors | B20: 10.855633 | C20: 11.467667 | D20: 12.105125 | E20: 11.812068 | F20: 11.715421 | G20: 11.382889 | H20: 9.274792 | I20: 9.836176 | J20: Department of Mineral and Petroleum Resources, energy balances, one file a year | K20: The department's total for all sectors. It is not the sales figure on the national balance sheet.
A21: Road transport | B21: 10.599969 | C21: 11.20332 | D21: 7.8504055 | E21: 7.799955 | F21: 9.421383 | G21: 10.179225 | H21: 8.15771 | I21: 8.734665 | J21: Department of Mineral and Petroleum Resources, energy balances, one file a year
A22: Rail | B22: 0.018827936 | C22: 0.047792777 | D22: 0.04603073 | E22: 0.05994 | F22: 0.035428523 | G22: 0.00079180579 | H22: 0.000738724 | I22: 0.00011681 | J22: Department of Mineral and Petroleum Resources, energy balances, one file a year
A23: Industry, all | B23: 0.023601798 | C23: 0.0060527821 | D23: 0.031182868 | E23: 0.10085648 | F23: 0.18482997 | G23: 0.18297078 | H23: 0.086091569 | I23: 0.06503531 | J23: Department of Mineral and Petroleum Resources, energy balances, one file a year | K23: Mining, construction, manufacturing and industry not specified, together. Manufacturing and other industry is this line less the two below.
A24: Mining (part of industry) | B24: 0.016619383 | C24: 0.0056376621 | D24: 0.0048052275 | E24: 0.072304039 | F24: 0.15942438 | G24: 0.15853869 | H24: 0.07227907 | I24: 0.05449402 | J24: Department of Mineral and Petroleum Resources, energy balances, one file a year
A25: Construction (part of industry) | B25: 0.006982415 | C25: 0.00041512 | D25: 0.0033661768 | E25: 0.0066261699 | F25: 0.0013684966 | G25: 0.00056973407 | H25: 0.00061182007 | I25: 0.00105943 | J25: Department of Mineral and Petroleum Resources, energy balances, one file a year
A26: Agriculture | B26: 0.15722427 | C26: 0.1724905 | D26: 1.9288791 | E26: 1.95126 | F26: 0.12049402 | G26: 0.10681195 | H26: 0.11402438 | I26: 0.12018356 | J26: Department of Mineral and Petroleum Resources, energy balances, one file a year
A27: Commercial and public services | B27: 0.0037713159 | C27: 0.003779845 | D27: 2.2438662 | E27: 1.8833842 | F27: 1.9471366 | G27: 0.90765475 | H27: 0.90489988 | I27: 0.90667726 | J27: Department of Mineral and Petroleum Resources, energy balances, one file a year | K27: Jumps from almost nothing to several billion litres from 2016: the department moved volumes between sectors, so read with care.
A28: Households | B28: 0.003343123 | C28: 0.002184249 | F28: 0.000179702 | G28: 0.000167353 | H28: 1.5799e-05 | I28: 1.481e-05 | J28: Department of Mineral and Petroleum Resources, energy balances, one file a year

Sheet DR01 sector activity
A1: DR01 Sector activity: mining, manufacturing and agriculture
A2: Activity is published to 2025; diesel by sector stops at 2021. The estimate for later years is the average diesel per unit of activity in 2018 to 2021 times the activity of that year. Diesel is read from the demand by sector sheet, not repeated here.
A5: Mining
A6: Line | B6: Unit | C6: 2014 | D6: 2015 | E6: 2016 | F6: 2017 | G6: 2018 | H6: 2019 | I6: 2020 | J6: 2021 | K6: 2022 | L6: 2023 | M6: 2024 | N6: 2025 | O6: Source | P6: Note
A7: Mining production volume | B7: index, 2019 = 100 | C7: 99.033333 | D7: 102.24167 | E7: 98.916667 | F7: 102.53333 | G7: 100.925 | H7: 99.983333 | I7: 89.1 | J7: 100.875 | K7: 93.008333 | L7: 93.016667 | M7: 93.533333 | N7: 93.708333 | O7: Statistics South Africa, Mining production and sales (P2041) | P7: Published to 2025.
A8: Diesel per unit of activity | B8: million litres per index point | C8: ='DR01 demand by sector'!B11*1000/C7 | D8: ='DR01 demand by sector'!C11*1000/D7 | E8: ='DR01 demand by sector'!D11*1000/E7 | F8: ='DR01 demand by sector'!E11*1000/F7 | G8: ='DR01 demand by sector'!F11*1000/G7 | H8: ='DR01 demand by sector'!G11*1000/H7 | I8: ='DR01 demand by sector'!H11*1000/I7 | J8: ='DR01 demand by sector'!I11*1000/J7 | O8: Calculated: diesel on the demand by sector sheet over the activity above | P8: The energy balance's mining line includes mines' haul trucks and road vehicles.
A9: Estimated diesel after 2021 | B9: billion litres | K9: =AVERAGE(G8:J8)*K7/1000 | L9: =AVERAGE(G8:J8)*L7/1000 | M9: =AVERAGE(G8:J8)*M7/1000 | N9: =AVERAGE(G8:J8)*N7/1000 | O9: Calculated: average diesel per unit of activity, 2018 to 2021, times that year's activity | P9: An estimate, not an observation and not an accepted model input. Holds diesel per unit of activity constant. For Nigel to agree.
A11: Manufacturing and other industry
A12: Line | B12: Unit | C12: 2014 | D12: 2015 | E12: 2016 | F12: 2017 | G12: 2018 | H12: 2019 | I12: 2020 | J12: 2021 | K12: 2022 | L12: 2023 | M12: 2024 | N12: 2025 | O12: Source | P12: Note
A13: Manufacturing production volume | B13: index, 2019 = 100 | C13: 100.11667 | D13: 100.1 | E13: 100.80833 | F13: 100.13333 | G13: 101.1 | H13: 99.983333 | I13: 87.666667 | J13: 93.116667 | K13: 93.141667 | L13: 93.716667 | M13: 93.333333 | N13: 92.141667 | O13: Statistics South Africa, Manufacturing production and sales (P3041.2) | P13: Published to 2025.
A14: Diesel per unit of activity | B14: million litres per index point | C14: =('DR01 demand by sector'!B10-'DR01 demand by sector'!B11-N('DR01 demand by sector'!B12))*1000/C13 | D14: =('DR01 demand by sector'!C10-'DR01 demand by sector'!C11-N('DR01 demand by sector'!C12))*1000/D13 | E14: =('DR01 demand by sector'!D10-'DR01 demand by sector'!D11-N('DR01 demand by sector'!D12))*1000/E13 | F14: =('DR01 demand by sector'!E10-'DR01 demand by sector'!E11-N('DR01 demand by sector'!E12))*1000/F13 | G14: =('DR01 demand by sector'!F10-'DR01 demand by sector'!F11-N('DR01 demand by sector'!F12))*1000/G13 | H14: =('DR01 demand by sector'!G10-'DR01 demand by sector'!G11-N('DR01 demand by sector'!G12))*1000/H13 | I14: =('DR01 demand by sector'!H10-'DR01 demand by sector'!H11-N('DR01 demand by sector'!H12))*1000/I13 | J14: =('DR01 demand by sector'!I10-'DR01 demand by sector'!I11-N('DR01 demand by sector'!I12))*1000/J13 | O14: Calculated: diesel on the demand by sector sheet over the activity above | P14: Diesel is industry less mining less construction. It is small (0.1 to 0.3 billion litres), so it moves with reclassification more than with output.
A15: Estimated diesel after 2021 | B15: billion litres | K15: =AVERAGE(G14:J14)*K13/1000 | L15: =AVERAGE(G14:J14)*L13/1000 | M15: =AVERAGE(G14:J14)*M13/1000 | N15: =AVERAGE(G14:J14)*N13/1000 | O15: Calculated: average diesel per unit of activity, 2018 to 2021, times that year's activity | P15: An estimate, not an observation and not an accepted model input. Holds diesel per unit of activity constant. For Nigel to agree.
A17: Agriculture
A18: Line | B18: Unit | C18: 2014 | D18: 2015 | E18: 2016 | F18: 2017 | G18: 2018 | H18: 2019 | I18: 2020 | J18: 2021 | K18: 2022 | L18: 2023 | M18: 2024 | N18: 2025 | O18: Source | P18: Note
A19: Agriculture, forestry and fishing real value added | B19: billion rand, 2015 prices | C19: 102.48769 | D19: 98.759569 | E19: 93.672105 | F19: 111.54508 | G19: 112.09493 | H19: 104.78476 | I19: 122.8701 | J19: 128.98309 | K19: 131.77064 | L19: 125.74664 | M19: 114.79164 | N19: 134.79675 | O19: Statistics South Africa, Gross domestic product (P0441) | P19: Published to 2025.
A20: Diesel per unit of activity | B20: million litres per billion rand | C20: ='DR01 demand by sector'!B13*1000/C19 | D20: ='DR01 demand by sector'!C13*1000/D19 | E20: ='DR01 demand by sector'!D13*1000/E19 | F20: ='DR01 demand by sector'!E13*1000/F19 | G20: ='DR01 demand by sector'!F13*1000/G19 | H20: ='DR01 demand by sector'!G13*1000/H19 | I20: ='DR01 demand by sector'!H13*1000/I19 | J20: ='DR01 demand by sector'!I13*1000/J19 | O20: Calculated: diesel on the demand by sector sheet over the activity above | P20: The balance's 2016 and 2017 figures are about double the other years and look like reclassification.
A21: Estimated diesel after 2021 | B21: billion litres | K21: =AVERAGE(G20:J20)*K19/1000 | L21: =AVERAGE(G20:J20)*L19/1000 | M21: =AVERAGE(G20:J20)*M19/1000 | N21: =AVERAGE(G20:J20)*N19/1000 | O21: Calculated: average diesel per unit of activity, 2018 to 2021, times that year's activity | P21: An estimate, not an observation and not an accepted model input. Holds diesel per unit of activity constant. For Nigel to agree.

Sheet DR04 routes and access
A1: DR04 Routes and access
A2: 66 facts from sources (blue), 6 calculated (white), 7 not available (yellow). Petrol and diesel only. Figures reported for several years are set out one column a year; every row names its source.
A5: Pipeline limit
A6: Item | B6: Asset or route | C6: Unit | D6: Basis | E6: 2021 | F6: 2022 | G6: 2023 | H6: 2024 | S6: Status | T6: Source | U6: Page | V6: Note
A7: Trunk line use | B7: Multi-product pipeline, Durban to Jameson Park | C7: million litres a week | D7: years to March | E7: 81 | F7: 91 | G7: 87 | H7: 97 | S7: From source | T7: Transnet Pipelines Report 2024, key performance indicators | U7: PDF p.5 | V7: About two thirds full in the year to March 2024: 97 a week is 5.0 billion litres a year. Not split by product. The target for the year to March 2025 was 104.
A8: Refined products moved, whole network | B8: All Transnet refined-product pipelines | C8: billion litres | D8: years to March | E8: 9 | F8: 9.79 | G8: 9.68 | H8: 9.51 | S8: From source | T8: Transnet Pipelines Report 2024, key performance indicators | U8: PDF p.5 | V8: Petrol and diesel grades on every Transnet line, including those fed by Natref and Secunda; jet fuel and crude are reported separately. Not the trunk line alone.
A9: Item | B9: Asset or route | C9: Unit | D9: Period | E9: Value | S9: Status | T9: Source | U9: Page | V9: Note
A10: Trunk line capacity | B10: Durban to Jameson Park, 24-inch multi-product line | C10: million litres a week | D10: as stated in 2020 | E10: 148 | S10: From source | T10: Transnet Pipelines 2020 report | U10: PDF p.3 | V10: Not confirmed as today's capacity; later phases and pump stations may have changed it.
A11: Trunk line capacity, annualised | B11: Durban to Jameson Park, 24-inch multi-product line | C11: billion litres a year | D11: as stated in 2020 | E11: 7.7 | S11: Calculated | T11: 148 million litres a week x 52 | U11: PDF p.3 | V11: Assumes every week at full rate; real annual capacity is lower.
A12: Trunk line capacity, latest statement | B12: Multi-product pipeline, Durban to Jameson Park | C12: million litres a week | D12: years to March 2021 to 2024, and the 2025 target | E12: 148 | S12: From source | T12: Transnet Pipelines Report 2024, key performance indicators | U12: PDF p.5 | V12: Unchanged from the 2020 figure: Transnet reports use against a capacity of 148 in every year. The latest report found is for the year to March 2024.
A13: Trunk line use, annualised | B13: Multi-product pipeline, Durban to Jameson Park | C13: billion litres a year | D13: year to March 2024 | E13: 5.04 | S13: Calculated | T13: 97 million litres a week x 52 | U13: PDF p.5 | V13: All refined products the line carried. Petrol and diesel are not reported separately.
A14: Inland accumulation facility | B14: Jameson Park, Gauteng (Transnet's TM2) | C14: million litres | D14: operational since December 2017 | E14: 180 | S14: From source | T14: Transnet Pipelines 2020 report | U14: PDF p.3 | V14: Working capacity by product not stated.
A15: Jameson Park and Transnet's storage sites out for proposal | B15: Jameson Park, Gauteng (Transnet's TM2) | D15: request for proposals, closes 4 December 2026 | E15: Not one of the five sites | S15: From source | T15: Transnet Pipelines, leasing opportunities: Kroonstad, Standerton, Magdala, Ladysmith and Bethlehem | V15: Transnet's own storage at Jameson Park is existing capacity beside Vopak Lesedi, which is connected to the same pipeline. Raised by Nigel on 9 October.
A16: Products carried on the trunk line | B16: Durban to Jameson Park | D16: as stated in 2020 | E16: Two diesel grades, two petrol grades, jet fuel | S16: From source | T16: Transnet Pipelines 2020 report | U16: PDF p.3
A17: Old Durban to Johannesburg pipeline | B17: Durban to Johannesburg (DJP) | D17: as stated in 2020 | E17: Being decommissioned; completion expected 2021 | S17: From source | T17: Transnet Pipelines 2020 report | U17: PDF p.3 | V17: Whether decommissioning is complete is not confirmed from a later source.
A18: Pipeline use as a share of capacity | B18: Transnet pipelines from Durban | C18: % | D18: as told to Parliament, 2026 | E18: About 70 | S18: From source | T18: Report of five Portfolio Committees on the Island View directive, 11 March 2026 (Parliament) | U18: section 3.1 | V18: The Minister of Transport's estimate, all products. New Island View leases are to require more use of the pipeline.
A20: Pipeline cost
A21: Item | B21: Asset or route | C21: Unit | D21: Basis | E21: 2023/24 | F21: 2024/25 | G21: 2025/26 | H21: 2026/27 | S21: Status | T21: Source | U21: Page | V21: Note
A22: Pipeline tariff, Durban to Alrode | B22: Durban to Alrode (Johannesburg) | C22: cents a litre | D22: financial years | E22: 61.74 | F22: 67.99 | S22: From source | T22: NERSA statement of 15 March 2024, as quoted by Engineering News | V22: Read from a news report quoting the regulator word for word; NERSA's own statement was not located. A 10.13% increase.
A23: Pipeline tariff, Durban to Alrode | B23: Durban to Alrode (Johannesburg) | C23: cents a litre | D23: financial years | G23: 73.22 | H23: 77.02 | S23: Calculated | T23: 67.99 plus the increases of 5.23 and 3.80 in NERSA's statement of 15 April 2025 | U23: p.1 | V23: Assumes the stated effect on the fuel price is the change in this tariff, as it was in 2024/25. To confirm in the reasons for decision.
A24: Item | B24: Asset or route | C24: Unit | D24: Period | E24: Value | S24: Status | T24: Source | U24: Page | V24: Note
A25: Effect of the tariff decision on the fuel price | B25: Durban to Johannesburg proxy | C25: cents a litre | D25: 2025/26; 2026/27 | E25: +5.23; +3.80 | S25: From source | T25: NERSA media statement, 15 April 2025 | U25: p.1 | V25: This is the change, not the tariff. The tariff by route is in the reasons for decision, not yet obtained.
A26: What the tariff covers | B26: Transnet's petroleum pipelines system | D26: decision of 27 February 2025 | E26: One set of tariffs for the whole licensed system; the department uses Durban to Alrode as its proxy for moving fuel from Durban to Johannesburg | S26: From source | T26: NERSA media statement, 15 April 2025 | U26: p.1 | V26: The statement does not say which products or which line each route tariff applies to; that is in the reasons for decision, not found online. Nigel to validate (call of 9 October).
A27: Tariff on routes other than Durban to Alrode | B27: Other inland routes | C27: cents a litre | D27: 2026/27 | E27: Not available | S27: Not available | T27: NERSA reasons for decision (not obtained) | V27: Needed to compare destinations other than Gauteng. NERSA's decisions pages were searched again on 9 October; the route table was not found online. Owner: Manish.
A29: Delivered cost
A30: Item | B30: Asset or route | C30: Unit | D30: Basis | E30: 2012 | F30: 2013 | G30: 2014 | H30: 2015 | I30: 2016 | J30: 2017 | K30: 2018 | L30: 2019 | M30: 2020 | N30: 2021 | O30: 2022 | P30: 2023 | Q30: 2024 | R30: 2025 | S30: Status | T30: Source | U30: Page | V30: Note
A31: Regulated transport cost to Gauteng in the diesel price | B31: Coast to Gauteng | C31: cents a litre | D31: year end | E31: 26.8 | F31: 28.9 | G31: 33.1 | H31: 35.3 | I31: 41 | J31: 41.5 | K31: 51.7 | L31: 57.4 | M31: 63.7 | N31: 64.9 | O31: 64.9 | P31: 75.7 | Q31: 75.7 | S31: From source | T31: Department of Mineral and Petroleum Resources, yearly price tables (levies, taxes and margins) | U31: Transport cost column | V31: The figure in the last month the department published for each year (April for 2024). It is reset each April. A regulated allowance, not a commercial rate. The April 2024 table shows 75.7 while the zone list of the same month shows 82.8.
A32: Regulated transport cost to Gauteng in the petrol price | B32: Coast to Gauteng | C32: cents a litre | D32: year end | E32: 26.8 | F32: 28.9 | G32: 28.9 | H32: 35.3 | I32: 41 | J32: 41.5 | K32: 51.7 | L32: 57.4 | M32: 63.7 | N32: 64.9 | O32: 67.9 | P32: 75.7 | Q32: 75.7 | S32: From source | T32: Department of Mineral and Petroleum Resources, yearly price tables (levies, taxes and margins) | U32: Transport cost column | V32: The figure in the last month the department published for each year (April for 2024). It is reset each April. A regulated allowance, not a commercial rate. The April 2024 table shows 75.7 while the zone list of the same month shows 82.8. The department's petrol table shows 28.9 throughout 2014, where its diesel table and zone list show 33.1 from April.
A33: Road freight income per tonne carried, all goods | B33: Road, South Africa | C33: rand a tonne | D33: calendar years | L33: 182 | Q33: 204 | R33: 205 | S33: Calculated | T33: Statistics South Africa, Land transport survey (P7162), July 2026 release | U33: series roadincf over roadpayl | V33: Income divided by payload. All goods and all distances together, so not a fuel rate or a route rate.
A34: Rail freight income per tonne carried, all goods | B34: Rail, South Africa | C34: rand a tonne | D34: calendar years | L34: 205 | Q34: 269 | R34: 272 | S34: Calculated | T34: Statistics South Africa, Land transport survey (P7162), July 2026 release | U34: series railincf over railpayl | V34: Income divided by payload. Mostly bulk minerals over long distances, so not a fuel rate.
A35: Item | B35: Asset or route | C35: Unit | D35: Basis | E35: 2024/25 | F35: 2025/26 | G35: 2026/27 | S35: Status | T35: Source | U35: Page | V35: Note
A36: Regulated transport differential less the pipeline tariff, Gauteng | B36: Coast to Gauteng | C36: cents a litre | D36: financial years | E36: 14.8 | F36: 13.9 | G36: 14.1 | S36: Calculated | T36: Gauteng differential (82.8, 87.1, 91.1) less the Durban to Alrode tariff (67.99, 73.22, 77.02) | V36: About 14 cents a litre in each year. What it pays for is not itemised in any document found: the department's working rules for the zone differentials were looked for on its site and in the price releases. The 2025 release shows the differentials are rebuilt from the pipeline tariff to each zone's supply point.
A37: Item | B37: Asset or route | C37: Unit | D37: Period | E37: Value | S37: Status | T37: Source | U37: Page | V37: Note
A38: Regulated price difference, inland less coast, diesel wholesale | B38: Gauteng less coast | C38: cents a litre | D38: July 2024 | E38: 79 | S38: From source | T38: Department of Mineral and Petroleum Resources, regulated fuel prices | V38: The regulated allowance for moving fuel inland, not an operator's actual cost. Coast series held ends November 2025.
A39: Regulated price difference, inland less coast, diesel wholesale | B39: Gauteng less coast | C39: cents a litre | D39: July 2025 | E39: 83.3 | S39: From source | T39: Department of Mineral and Petroleum Resources, regulated fuel prices | V39: The regulated allowance for moving fuel inland, not an operator's actual cost. Coast series held ends November 2025.
A40: Regulated price difference, inland less coast, diesel wholesale | B40: Gauteng less coast | C40: cents a litre | D40: November 2025 | E40: 83.3 | S40: From source | T40: Department of Mineral and Petroleum Resources, regulated fuel prices | V40: The regulated allowance for moving fuel inland, not an operator's actual cost. Coast series held ends November 2025.
A41: Regulated transport differential, Gauteng (zone 9C) | B41: Coast to Gauteng | C41: cents a litre | D41: April 2014 | E41: 33.1 | S41: From source | T41: Department zone lists (2014, 2024); Central Energy Fund price composition (2025, 2026) | U41: CEF p.3 | V41: The regulated allowance for getting petrol and diesel to Gauteng, which the regulator ties to the pipeline tariff. Not a commercial rate.
A42: Regulated transport differential, Gauteng (zone 9C) | B42: Coast to Gauteng | C42: cents a litre | D42: April 2024 | E42: 82.8 | S42: From source | T42: Department zone lists (2014, 2024); Central Energy Fund price composition (2025, 2026) | U42: CEF p.3 | V42: The regulated allowance for getting petrol and diesel to Gauteng, which the regulator ties to the pipeline tariff. Not a commercial rate.
A43: Regulated transport differential, Gauteng (zone 9C) | B43: Coast to Gauteng | C43: cents a litre | D43: June 2025 | E43: 87.1 | S43: From source | T43: Department zone lists (2014, 2024); Central Energy Fund price composition (2025, 2026) | U43: CEF p.3 | V43: The regulated allowance for getting petrol and diesel to Gauteng, which the regulator ties to the pipeline tariff. Not a commercial rate.
A44: Regulated transport differential, Gauteng (zone 9C) | B44: Coast to Gauteng | C44: cents a litre | D44: April 2026 | E44: 91.1 | S44: From source | T44: Department zone lists (2014, 2024); Central Energy Fund price composition (2025, 2026) | U44: CEF p.3 | V44: The regulated allowance for getting petrol and diesel to Gauteng, which the regulator ties to the pipeline tariff. Not a commercial rate.
...

Sheet DR04 entry points
A1: DR04 Where petrol and diesel imports enter
A2: Billion litres, calendar years. Petrol and diesel only. The office is where the fuel was cleared through customs: the nearest public record of the entry point, not a berth or terminal record.
A4: Entry point | B4: Route | C4: 2014 | D4: 2015 | E4: 2016 | F4: 2017 | G4: 2018 | H4: 2019 | I4: 2020 | J4: 2021 | K4: 2022 | L4: 2023 | M4: 2024 | N4: 2025 | O4: Source | P4: Note
A5: Diesel
A6: Durban | B6: Sea | C6: 3.4012934 | D6: 4.0427003 | E6: 3.441357 | F6: 4.8765373 | G6: 3.9859041 | H6: 3.8091433 | I6: 3.8259377 | J6: 5.8348732 | K6: 7.881248 | L6: 9.1250365 | M6: 8.0328899 | N6: 8.9315354 | O6: SARS customs, imports by office of clearance (fuel_trade_sars_by_office.csv) | P6: Includes fuel for the inland pipeline and for the coast.
A7: Cape Town | B7: Sea | C7: 0.56348507 | D7: 0.99664213 | E7: 0.21495197 | F7: 0.39464311 | G7: 0.51313339 | H7: 0.60156129 | I7: 1.8427224 | J7: 2.3507153 | K7: 2.485097 | L7: 1.3875841 | M7: 0.95747643 | N7: 1.3353922 | O7: SARS customs, imports by office of clearance (fuel_trade_sars_by_office.csv)
A8: Mossel Bay | B8: Sea | C8: 0.77085345 | D8: 0.95190812 | E8: 0.39227171 | F8: 0.29025052 | G8: 0.13823706 | H8: 0.71375255 | I8: 0.40019393 | J8: 0.67467583 | K8: 0.56689835 | L8: 1.0931506 | M8: 0.57338465 | N8: 0.5217978 | O8: SARS customs, imports by office of clearance (fuel_trade_sars_by_office.csv)
A9: East London | B9: Sea | C9: 0.059488792 | D9: 0.10177181 | E9: 0.07380239 | F9: 0.083400489 | G9: 0.066186531 | H9: 0.073540293 | I9: 0.19997504 | J9: 0.20686197 | K9: 0.18968079 | L9: 0.35138882 | M9: 0.51376771 | N9: 0.40330738 | O9: SARS customs, imports by office of clearance (fuel_trade_sars_by_office.csv)
A10: Port Elizabeth | B10: Sea | C10: 0.045097549 | D10: 0.095793462 | E10: 0.06197985 | F10: 0.05229008 | G10: 0.099219997 | H10: 0.085687549 | I10: 0.19170736 | J10: 0.2561779 | K10: 0.22513035 | L10: 0.33666737 | M10: 0.13769844 | N10: 0.31335745 | O10: SARS customs, imports by office of clearance (fuel_trade_sars_by_office.csv)
A11: Richards Bay | B11: Sea | C11: 0 | D11: 0 | E11: 0 | F11: 0.10571482 | G11: 0.091830959 | H11: 0.093812929 | I11: 0.14679285 | J11: 0.23403682 | K11: 0.33131979 | L11: 0.3207667 | M11: 0.39078248 | N11: 0.6579146 | O11: SARS customs, imports by office of clearance (fuel_trade_sars_by_office.csv)
A12: Komatipoort | B12: Road, from Mozambique | C12: 0.1510623 | D12: 0.257288 | E12: 0.23679602 | F12: 0.23388003 | G12: 0.22802977 | H12: 0.2127269 | I12: 0.20753876 | J12: 0.20133574 | K12: 0.27415852 | L12: 0.25457084 | M12: 0.18582006 | N12: 0.082022506 | O12: SARS customs, imports by office of clearance (fuel_trade_sars_by_office.csv) | P12: The only recorded entry from the Maputo and Matola side.
A13: Other offices | B13: Land borders and inland offices | C13: 0.00043176669 | D13: 0.0046752559 | E13: 0.0031359737 | F13: 0.00074357618 | G13: 0.00041767239 | H13: 4.726407e-05 | I13: 0.00011745485 | J13: 0.0027185497 | K13: 0.000723718 | L13: 0.00086713425 | M13: 0.00072742656 | N13: 0.0033929065 | O13: SARS customs, imports by office of clearance (fuel_trade_sars_by_office.csv)
A14: All offices | C14: =SUM(C6:C13) | D14: =SUM(D6:D13) | E14: =SUM(E6:E13) | F14: =SUM(F6:F13) | G14: =SUM(G6:G13) | H14: =SUM(H6:H13) | I14: =SUM(I6:I13) | J14: =SUM(J6:J13) | ... N14: =SUM(N6:N13) | O14: Sum of the rows above; equals SARS national imports on the History sheet
A15: Durban share | C15: =IF(C14=0,"",C6/C14) | D15: =IF(D14=0,"",D6/D14) | E15: =IF(E14=0,"",E6/E14) | F15: =IF(F14=0,"",F6/F14) | G15: =IF(G14=0,"",G6/G14) | H15: =IF(H14=0,"",H6/H14) | I15: =IF(I14=0,"",I6/I14) | J15: =IF(J14=0,"",J6/J14) | ... N15: =IF(N14=0,"",N6/N14) | O15: Calculated: Durban over all offices
A17: Petrol
A18: Durban | B18: Sea | C18: 0.85247094 | D18: 1.4425428 | E18: 1.13647 | F18: 1.7292857 | G18: 1.5364388 | H18: 1.2563484 | I18: 0.66409273 | J18: 2.4365647 | K18: 3.8826694 | L18: 4.1655992 | M18: 3.8047252 | N18: 4.2289797 | O18: SARS customs, imports by office of clearance (fuel_trade_sars_by_office.csv) | P18: Includes fuel for the inland pipeline and for the coast.
A19: Cape Town | B19: Sea | C19: 0.18750103 | D19: 0.26259419 | E19: 0.058894374 | F19: 0.21050907 | G19: 0.18265634 | H19: 0.11619286 | I19: 1.0027419 | J19: 1.4319451 | K19: 1.5003409 | L19: 0.23304926 | M19: 0.131091 | N19: 0.18559754 | O19: SARS customs, imports by office of clearance (fuel_trade_sars_by_office.csv)
A20: Mossel Bay | B20: Sea | C20: 0 | D20: 0 | E20: 0.010228015 | F20: 0 | G20: 0 | H20: 0.046954148 | I20: 0 | J20: 0.099757575 | K20: 0.034555764 | L20: 0.068691824 | M20: 0.049694999 | N20: 0 | O20: SARS customs, imports by office of clearance (fuel_trade_sars_by_office.csv)
A21: East London | B21: Sea | C21: 0.069111017 | D21: 0.10173686 | E21: 0.083706491 | F21: 0.069640116 | G21: 0.018334526 | H21: 0 | I21: 0.0118587 | J21: 0 | K21: 0.005168638 | L21: 0.008596477 | M21: 0.013139503 | N21: 0.031405816 | O21: SARS customs, imports by office of clearance (fuel_trade_sars_by_office.csv)
A22: Port Elizabeth | B22: Sea | C22: 0.041048641 | D22: 0.062738178 | E22: 0.070599366 | F22: 0.019982608 | G22: 0.014892632 | H22: 0.0010843011 | I22: 0.00077485668 | J22: 0.00078124021 | K22: 0.0037131559 | L22: 0.0067097924 | M22: 0.0011940559 | N22: 0.0030697401 | O22: SARS customs, imports by office of clearance (fuel_trade_sars_by_office.csv)
A23: Richards Bay | B23: Sea | C23: 0 | D23: 0 | E23: 0 | F23: 0.038417234 | G23: 0.03354092 | H23: 0.018129952 | I23: 0.009266228 | J23: 0 | K23: 0 | L23: 0 | M23: 0 | N23: 0 | O23: SARS customs, imports by office of clearance (fuel_trade_sars_by_office.csv)
A24: Komatipoort | B24: Road, from Mozambique | C24: 0 | D24: 0 | E24: 0.034672613 | F24: 0.046040565 | G24: 0.04390319 | H24: 0.038667509 | I24: 0.030842959 | J24: 0.039454367 | K24: 0.028805741 | L24: 0.000125422 | M24: 0.001009567 | N24: 0.004416485 | O24: SARS customs, imports by office of clearance (fuel_trade_sars_by_office.csv) | P24: The only recorded entry from the Maputo and Matola side.
A25: Other offices | B25: Land borders and inland offices | C25: 6.319224e-05 | D25: 3.317238e-05 | E25: 0.0010675928 | F25: 0.0002811756 | G25: 4.86485e-06 | H25: 8.68e-06 | I25: 9.5671e-05 | J25: 0.00010978057 | K25: 8.26079e-06 | L25: 2.756e-06 | M25: 8.455e-08 | N25: 1.854e-06 | O25: SARS customs, imports by office of clearance (fuel_trade_sars_by_office.csv)
A26: All offices | C26: =SUM(C18:C25) | D26: =SUM(D18:D25) | E26: =SUM(E18:E25) | F26: =SUM(F18:F25) | G26: =SUM(G18:G25) | H26: =SUM(H18:H25) | I26: =SUM(I18:I25) | J26: =SUM(J18:J25) | ... N26: =SUM(N18:N25) | O26: Sum of the rows above; equals SARS national imports on the History sheet
A27: Durban share | C27: =IF(C26=0,"",C18/C26) | D27: =IF(D26=0,"",D18/D26) | E27: =IF(E26=0,"",E18/E26) | F27: =IF(F26=0,"",F18/F26) | G27: =IF(G26=0,"",G18/G26) | H27: =IF(H26=0,"",H18/H26) | I27: =IF(I26=0,"",I18/I26) | J27: =IF(J26=0,"",J18/J26) | ... N27: =IF(N26=0,"",N18/N26) | O27: Calculated: Durban over all offices
A29: Diesel and petrol
A30: Durban | B30: Sea | C30: 4.2537643 | D30: 5.4852431 | E30: 4.5778271 | F30: 6.605823 | G30: 5.5223429 | H30: 5.0654917 | I30: 4.4900304 | J30: 8.2714379 | K30: 11.763917 | L30: 13.290636 | M30: 11.837615 | N30: 13.160515 | O30: SARS customs, imports by office of clearance (fuel_trade_sars_by_office.csv) | P30: Includes fuel for the inland pipeline and for the coast.
A31: Cape Town | B31: Sea | C31: 0.7509861 | D31: 1.2592363 | E31: 0.27384635 | F31: 0.60515219 | G31: 0.69578973 | H31: 0.71775415 | I31: 2.8454643 | J31: 3.7826604 | K31: 3.9854379 | L31: 1.6206334 | M31: 1.0885674 | N31: 1.5209897 | O31: SARS customs, imports by office of clearance (fuel_trade_sars_by_office.csv)
A32: Mossel Bay | B32: Sea | C32: 0.77085345 | D32: 0.95190812 | E32: 0.40249973 | F32: 0.29025052 | G32: 0.13823706 | H32: 0.7607067 | I32: 0.40019393 | J32: 0.7744334 | K32: 0.60145411 | L32: 1.1618424 | M32: 0.62307965 | N32: 0.5217978 | O32: SARS customs, imports by office of clearance (fuel_trade_sars_by_office.csv)
A33: East London | B33: Sea | C33: 0.12859981 | D33: 0.20350867 | E33: 0.15750888 | F33: 0.15304061 | G33: 0.084521057 | H33: 0.073540293 | I33: 0.21183374 | J33: 0.20686197 | K33: 0.19484943 | L33: 0.3599853 | M33: 0.52690721 | N33: 0.43471319 | O33: SARS customs, imports by office of clearance (fuel_trade_sars_by_office.csv)
A34: Port Elizabeth | B34: Sea | C34: 0.08614619 | D34: 0.15853164 | E34: 0.13257922 | F34: 0.072272688 | G34: 0.11411263 | H34: 0.08677185 | I34: 0.19248222 | J34: 0.25695914 | K34: 0.2288435 | L34: 0.34337717 | M34: 0.1388925 | N34: 0.31642719 | O34: SARS customs, imports by office of clearance (fuel_trade_sars_by_office.csv)
A35: Richards Bay | B35: Sea | C35: 0 | D35: 0 | E35: 0 | F35: 0.14413206 | G35: 0.12537188 | H35: 0.11194288 | I35: 0.15605907 | J35: 0.23403682 | K35: 0.33131979 | L35: 0.3207667 | M35: 0.39078248 | N35: 0.6579146 | O35: SARS customs, imports by office of clearance (fuel_trade_sars_by_office.csv)
A36: Komatipoort | B36: Road, from Mozambique | C36: 0.1510623 | D36: 0.257288 | E36: 0.27146864 | F36: 0.2799206 | G36: 0.27193296 | H36: 0.25139441 | I36: 0.23838172 | J36: 0.24079011 | K36: 0.30296427 | L36: 0.25469626 | M36: 0.18682963 | N36: 0.086438991 | O36: SARS customs, imports by office of clearance (fuel_trade_sars_by_office.csv) | P36: The only recorded entry from the Maputo and Matola side.
A37: Other offices | B37: Land borders and inland offices | C37: 0.00049495893 | D37: 0.0047084283 | E37: 0.0042035665 | F37: 0.0010247518 | G37: 0.00042253724 | H37: 5.594407e-05 | I37: 0.00021312585 | J37: 0.0028283303 | K37: 0.00073197879 | L37: 0.00086989025 | M37: 0.00072751111 | N37: 0.0033947605 | O37: SARS customs, imports by office of clearance (fuel_trade_sars_by_office.csv)
A38: All offices | C38: =SUM(C30:C37) | D38: =SUM(D30:D37) | E38: =SUM(E30:E37) | F38: =SUM(F30:F37) | G38: =SUM(G30:G37) | H38: =SUM(H30:H37) | I38: =SUM(I30:I37) | J38: =SUM(J30:J37) | ... N38: =SUM(N30:N37) | O38: Sum of the rows above; equals SARS national imports on the History sheet
A39: Durban share | C39: =IF(C38=0,"",C30/C38) | D39: =IF(D38=0,"",D30/D38) | E39: =IF(E38=0,"",E30/E38) | F39: =IF(F38=0,"",F30/F38) | G39: =IF(G38=0,"",G30/G38) | H39: =IF(H38=0,"",H30/H38) | I39: =IF(I38=0,"",I30/I38) | J39: =IF(J38=0,"",J30/J38) | ... N39: =IF(N38=0,"",N30/N38) | O39: Calculated: Durban over all offices

Sheet DR04 transport cost
A1: DR04 Regulated cost of moving petrol and diesel
A2: Cents a litre. These are regulated allowances in the fuel price, set by the department and the energy regulator. They are not what a haulier or Transnet charges a shipper: commercial road and rail rates are not published.
A4: Durban to Gauteng, by element
A5: Element | B5: 2024/25 | C5: 2025/26 | D5: 2026/27 | E5: Basis | H5: Source
A6: Pipeline tariff, Durban to Alrode | B6: 67.99 | C6: 73.22 | D6: 77.02 | E6: 2024/25 as reported; later years calculated by adding NERSA's stated increases | H6: NERSA statements of 15 March 2024 (as quoted by Engineering News) and 15 April 2025
A7: Regulated transport differential, Gauteng (zone 9C) | B7: 82.8 | D7: 91.1 | E7: Regulated allowance in the petrol and diesel price for transport from the coast | H7: Department zone list, April 2024; Central Energy Fund price composition, 1 April 2026
A8: Regulated secondary storage | B8: 36.6 | D8: 39 | E8: Regulated allowance for depot storage; one national figure | H8: Department diesel margins, 2024; Central Energy Fund price composition, 1 April 2026
A9: Regulated secondary distribution | B9: 17.2 | D9: 19.1 | E9: Regulated allowance for road delivery from depot to service station; one national figure | H9: Department diesel margins, 2024; Central Energy Fund price composition, 1 April 2026
A10: Commercial road tanker rate, Durban to Gauteng | E10: Not published | H10: None found; needs Vopak or a haulier
A11: Rail rate, Durban to Gauteng | E11: Not published | H11: None found; needs Transnet or Vopak
A13: Regulated transport differential by pricing zone (the same for petrol and diesel in 2014; diesel list for 2024)
A14: Zone | B14: Provinces | C14: Districts | D14: Examples | E14: 2014 | F14: 2024 | G14: Change | H14: Source
A15: 9C (Gauteng) | B15: Gauteng, Mpumalanga, Free State, North West | C15: 51 | D15: Alberton, Bafokeng, Balfour, Benoni, Bethal, Boksburg | E15: 33.1 | F15: 82.8 | G15: =IF(COUNT(E15,F15)<2,"",F15-E15) | H15: Department of Mineral and Petroleum Resources, zone lists effective 2 April 2014 and 3 April 2024
A16: 57C | B16: Mpumalanga, KwaZulu Natal | C16: 3 | D16: Paulpietersburg, Utrecht, Volksrust | E16: 30.5 | F16: 75.7 | G16: =IF(COUNT(E16,F16)<2,"",F16-E16) | H16: Department of Mineral and Petroleum Resources, zone lists effective 2 April 2014 and 3 April 2024
A17: 58C | B17: Mpumalanga, KwaZulu Natal | C17: 3 | D17: Piet Retief, Simdlangentsha, Wakkerstroom | E17: 35.4 | F17: 93.1 | G17: =IF(COUNT(E17,F17)<2,"",F17-E17) | H17: Department of Mineral and Petroleum Resources, zone lists effective 2 April 2014 and 3 April 2024
A18: 8C | B18: Mpumalanga, Free State | C18: 14 | D18: Amersfoort, Clocolan, Ermelo, Ficksburg, Frankfort, Heilbron | E18: 35.4 | F18: 93.1 | G18: =IF(COUNT(E18,F18)<2,"",F18-E18) | H18: Department of Mineral and Petroleum Resources, zone lists effective 2 April 2014 and 3 April 2024
A19: 10C | B19: Mpumalanga, Free State, North West, Limpopo | C19: 28 | D19: Bela-Bela (Warmbad), Belfast, Bloemhof, Brandfort, Bultfontein, Carolina | E19: 44.3 | F19: 104 | G19: =IF(COUNT(E19,F19)<2,"",F19-E19) | H19: Department of Mineral and Petroleum Resources, zone lists effective 2 April 2014 and 3 April 2024
A20: 61C | B20: Mpumalanga, Limpopo | C20: 8 | D20: Barberton, Mapulaneng, Mhala, Nelspruit, Nkomazi (Kamhulshwa), Nsikazi (Kangwane) | E20: 59.2 | F20: 128 | G20: =IF(COUNT(E20,F20)<2,"",F20-E20) | H20: Department of Mineral and Petroleum Resources, zone lists effective 2 April 2014 and 3 April 2024
A21: 6C | B21: Free State, KwaZulu Natal | C21: 8 | D21: Bergville, Dannhauser, Dundee, Glencoe, Harrismith, Newcastle | E21: 24.2 | F21: 59.1 | G21: =IF(COUNT(E21,F21)<2,"",F21-E21) | H21: Department of Mineral and Petroleum Resources, zone lists effective 2 April 2014 and 3 April 2024
A22: 7C | B22: Free State | C22: 3 | D22: Bethlehem, Fouriesburg, Witsieshoek | E22: 30.5 | F22: 75.7 | G22: =IF(COUNT(E22,F22)<2,"",F22-E22) | H22: Department of Mineral and Petroleum Resources, zone lists effective 2 April 2014 and 3 April 2024
A23: 8A | B23: Free State, Eastern Cape, Northern Cape | C23: 20 | D23: Barkly East, Bethulie, Colesberg, De Aar, Edenburg, Elliot | E23: 55.2 | F23: 87.6 | G23: =IF(COUNT(E23,F23)<2,"",F23-E23) | H23: Department of Mineral and Petroleum Resources, zone lists effective 2 April 2014 and 3 April 2024
A24: 9A | B24: Free State, Northern Cape | C24: 6 | D24: Britstown, Fauresmith, Hopetown, Koffiefontein, Philipstown, Prieska | E24: 72.1 | F24: 114.4 | G24: =IF(COUNT(E24,F24)<2,"",F24-E24) | H24: Department of Mineral and Petroleum Resources, zone lists effective 2 April 2014 and 3 April 2024
A25: 11C | B25: Free State, North West, Limpopo, Northern Cape | C25: 23 | D25: Barkly West, Bloemfontein, Boshof, Botshabelo, Delareyville, Dewetsdorp | E25: 59.2 | F25: 128 | G25: =IF(COUNT(E25,F25)<2,"",F25-E25) | H25: Department of Mineral and Petroleum Resources, zone lists effective 2 April 2014 and 3 April 2024
A26: 12C | B26: North West, Limpopo | C26: 6 | D26: Ditsobotla, Polokwane (Pietersburg) (south of tropic of capricorn), Seshego, Thabamoopo, Thabazimbi (east of 27o longitude), Vryburg (south of 26o30' latitude) | E26: 65 | F26: 132.8 | G26: =IF(COUNT(E26,F26)<2,"",F26-E26) | H26: Department of Mineral and Petroleum Resources, zone lists effective 2 April 2014 and 3 April 2024
... A66: 17A | B66: Northern Cape | C66: 1 | D66: Gordonia Central (between 27o30' and 28o latituded) | E66: 99.8 | F66: 179.6 | G66: =IF(COUNT(E66,F66)<2,"",F66-E66) | H66: Department of Mineral and Petroleum Resources, zone lists effective 2 April 2014 and 3 April 2024
A67: 60C | B67: Not in the 2014 district list | E67: 44.3 | F67: 104 | G67: =IF(COUNT(E67,F67)<2,"",F67-E67) | H67: Department of Mineral and Petroleum Resources, zone lists effective 2 April 2014 and 3 April 2024
A68: 10A | B68: Not in the 2014 district list | E68: 82.6 | F68: 121.5 | G68: =IF(COUNT(E68,F68)<2,"",F68-E68) | H68: Department of Mineral and Petroleum Resources, zone lists effective 2 April 2014 and 3 April 2024

Sheet DR07 demand evidence
A1: DR07 Demand evidence
A2: 75 facts from sources (blue), 21 calculated (white), 5 not available (yellow). Petrol and diesel only. Figures reported for several years are set out one column a year; every row names its source.
A5: Power generation
A6: Item | B6: Covers | C6: Unit | D6: Basis | E6: 2016 | F6: 2017 | G6: 2018 | H6: 2019 | I6: 2020 | J6: 2021 | K6: 2022 | L6: 2023 | M6: 2024 | N6: 2025 | O6: 2026 | P6: Status | Q6: Source | R6: Page | S6: Note
A7: Fuel burned at Eskom's turbines, as reported | B7: Eskom: Ankerlig, Gourikwa, Acacia, Port Rex | C7: million litres | D7: years to March | E7: 1247.8 | F7: 10 | G7: 37.8 | H7: 385 | I7: 426.2 | J7: 458.7 | K7: 580.4 | L7: 937.5 | M7: 1129.5 | N7: 679.1 | P7: From source | Q7: Eskom Integrated Report 2025, technical statistics | R7: PDF p.141 | S7: Eskom reports diesel and kerosene together. Acacia and Port Rex burn kerosene and are 342 MW of Eskom's 2,426 MW, so nearly all of it is diesel. 2026 is not yet reported.
A8: Electricity generated at Eskom's turbines | B8: Eskom | C8: GWh | D8: years to March | K8: 1826 | L8: 3018 | M8: 3634 | N8: 2176 | O8: 811 | P8: From source | Q8: Eskom data portal and reports
A9: Litres burned per kWh, implied | B9: Eskom | C9: litres per kWh | D9: years to March | K9: 0.318 | L9: 0.311 | M9: 0.311 | N9: 0.312 | P9: Calculated | Q9: Reported fuel divided by reported generation | S9: Confirms the 0.31 litres per kWh used on the Power fleet sheet.
A10: Electricity generated at independent diesel plants | B10: Avon and Dedisa | C10: GWh | D10: years to March | L10: 1098 | M10: 1509 | N10: 662 | O10: 268 | P10: From source | Q10: Eskom data portal and reports
A11: Diesel burned at independent plants, estimated | B11: Avon and Dedisa | C11: million litres | D11: years to March | L11: 340 | M11: 468 | N11: 205 | O11: 83 | P11: Calculated | Q11: Generation x 0.31 litres per kWh | S11: The producers do not report litres. Uses Eskom's implied rate.
A12: Electricity not supplied through load-shedding | B12: Electricity not supplied through load-shedding | C12: TWh | D12: calendar years | L12: 10.6 | M12: 2.5 | P12: From source | Q12: CSIR, Utility-scale power generation statistics in South Africa 2024 | R12: PDF p.4 | S12: An upper limit: each stage is counted as its full megawatts for the full hour.
